Workbook

Sheet 2024_원단커버
A1: 주문 접수일시 | B1: 판매처 주문일자 | C1: 제작번호 | D1: 판매업체명 | E1: 판매처 주문번호 | F1: 제작상품 (판매상품명/옵션) | G1: 주문수량 | H1: 주문자명 | I1: 주문상태 | J1: 페이지수 | K1: =SUBTOTAL(9,G2:G999) -> 21
A2: 45597.817 | B2: 45597 | C2: 20241101-000000017 | D2: 스탑북 | E2: 20241101193025CB0C | F2: 러브데이북 (러브데이북_280_210_기성커버 / 280X210 | 기본금박(무료) | 없음 | 38p | 모던그레이(기본금박)) | G2: 1 | H2: 김장헌 | I2: 발송완료 | J2: 60
A3: 45599.7 | B3: 45599 | C3: 20241103-000000030 | D3: 스탑북 | E3: 20241103164338F7F4 | F3: 드림클래스_가로타입_276_197 (포토그랩스_276_197_기성 원단커버(가변 스티커) / 276X197 | 하드커버 | 없음 | 48p) | G3: 1 | H3: 박주희 | I3: 발송완료 | J3: 42
A4: 45600.538 | B4: 45600 | C4: 20241104-000000026 | D4: 스탑북 | E4: 2024110412494579BD | F4: 러브데이북 (러브데이북_280_210_기성커버 / 280X210 | 기본금박(무료) | 없음 | 38p | 러블리핑크(기본금박)) | G4: 1 | H4: 최현 | I4: 발송완료 | J4: 46
A5: 45600.609 | B5: 45600 | C5: 20241104-000000048 | D5: 스탑북 | E5: 202411041432437D15 | F5: 드림클래스_가로타입_276_197 (포토그랩스_276_197_기성 원단커버(가변 스티커) / 276X197 | 하드커버 | 없음 | 48p) | G5: 1 | H5: 박주희 | I5: 발송완료 | J5: 46
A6: 45600.922 | B6: 45600 | C6: 20241104-000000068 | D6: 스탑북 | E6: 20241104220001832C | F6: 러브데이북 (러브데이북_280_210_기성커버 / 280X210 | 기본금박(무료) | 없음 | 38p | 러블리핑크(기본금박)) | G6: 1 | H6: 이행원 | I6: 발송완료 | J6: 46
A7: 45601.461 | B7: 45601 | C7: 20241105-000000009 | D7: 스탑북 | E7: 2024110510581417C0 | F7: 시크북(북타입)_210_280_기성 원단커버 (시크북(북타입)_210_280_58p_기성 원단커버 / 210X280 | 하드커버 | 없음 | 58p | 로만브라운) | G7: 1 | H7: 김경훈 | I7: 발송완료 | J7: 60
A8: 45601.86 | B8: 45601 | C8: 20241105-000000034 | D8: 스탑북 | E8: 20241105203132F72F | F8: 드림클래스_가로타입_276_197 (포토그랩스_276_197_기성 원단커버(가변 스티커) / 276X197 | 하드커버 | 없음 | 48p) | G8: 1 | H8: 이은미 | I8: 발송완료 | J8: 48
A9: 45602.143 | B9: 45602 | C9: 20241106-000000004 | D9: 스탑북 | E9: 202411060322466F98 | F9: 드림클래스_정사각 타입_248_248 (플라이트북_248_248_소프트 압축 커버 / 248X248 | 소프트압축커버 | 없음 | 48p) | G9: 1 | H9: 윤태경 | I9: 발송완료 | J9: 60
A10: 45602.381 | B10: 45602 | C10: 20241106-000000005 | D10: 스탑북 | E10: 20241106090202E0BC | F10: 드림클래스_세로타입_210_273 (플라이트북_210_273_소프트 압축 커버 / 210X273 | 소프트압축커버 | 없음 | 48p) | G10: 1 | H10: 박예슬 | I10: 발송완료 | J10: 50
A11: 45602.652 | B11: 45602 | C11: 20241106-000000026 | D11: 스탑북 | E11: 20241106153402C9EA | F11: 드림클래스_가로타입_276_197 (포토그랩스_276_197_기성 원단커버(가변 스티커) / 276X197 | 하드커버 | 없음 | 48p) | G11: 1 | H11: 정효정 | I11: 발송완료 | J11: 50
A12: 45603.39 | B12: 45602 | C12: 20241106-000000042 | D12: 스탑북 | E12: 20241106205551C2D1 | F12: 러브데이북 (러브데이북_280_210_기성커버 / 280X210 | 기본금박(무료) | 없음 | 38p | 모던그레이(기본금박)) | G12: 1 | H12: 박세진 | I12: 취소완료 | J12: 58
A13: 45603.739 | B13: 45603 | C13: 20241107-000000024 | D13: 스탑북 | E13: 2024110717373896FC | F13: 시크북(앨범타입)_210_280_기성원단커버 (시크북(앨범타입)_210_280_20p_기성 원단커버 / 210X280 | 압축앨범 | 없음 | 20p | 로만브라운) | G13: 1 | H13: 문수현 | I13: 발송완료 | J13: 20
... A94: 45638.519 | B94: 45638 | C94: 20241212-000000137 | D94: 스탑북 | E94: 20241212121527462F | F94: 시크북(북타입)_210_280_기성 원단커버 (시크북(북타입)_210_280_58p_기성 원단커버 / 210X280 | 하드커버 | 없음 | 58p | 로만브라운) | G94: 1 | H94: 윤형진 | I94: 발송완료 | J94: 60
A95: 45639.522 | B95: 45639 | C95: 20241213-000000032 | D95: 스탑북 | E95: 2.0241213e+124 | F95: 레더북 (레더북_210_280_원단커버 포토북 / 210X280 | 원단커버_실제본 | 없음 | 38p | 커버타이틀 1 | 다크네이비) | G95: 6 | H95: 안선 | I95: 발송완료 | J95: 44
A96: 45639.657 | B96: 45639 | C96: 20241213-000000090 | D96: 스탑북 | E96: 2024121314382522C5 | F96: 드림클래스_세로타입_210_273 (포토그랩스pro_210_273_기성 원단커버(가변 스티커) / 210X273 | 하드커버 | 없음 | 48p) | G96: 1 | H96: 이지연 | I96: 발송완료 | J96: 40
A97: 45639.692 | B97: 45639 | C97: 20241213-000000104 | D97: 스탑북 | E97: 20241213163128228B | F97: 드림클래스_가로타입_276_197 (포토그랩스pro_276_197_기성 원단커버(가변 스티커) / 276X197 | 하드커버 | 없음 | 48p) | G97: 9 | H97: 박찬규 | I97: 발송완료 | J97: 54
A98: 45639.722 | B98: 45639 | C98: 20241213-000000106 | D98: 스탑북 | E98: 202412131715501AFF | F98: 레더북 (레더북_210_280_원단커버 포토북 / 210X280 | 원단커버_실제본 | 없음 | 38p | 커버타이틀 1 | 다크네이비) | G98: 1 | H98: 장재혁 | I98: 발송완료 | J98: 52
A99: 45640.416 | B99: 45640 | C99: 20241214-000000011 | D99: 스탑북 | E99: 20241214095133DB94 | F99: 드림클래스_가로타입_276_197 (포토그랩스_276_197_기성 원단커버(가변 스티커) / 276X197 | 하드커버 | 없음 | 48p) | G99: 1 | H99: 박주희 | I99: 발송완료 | J99: 40
A100: 45641.929 | B100: 45641 | C100: 20241215-000000048 | D100: 스탑북 | E100: 20241215220656AB02 | F100: 러브데이북 (러브데이북_280_210_기성커버 / 280X210 | 기본금박(무료) | 없음 | 38p | 퓨어아이보리(기본금박)) | G100: 1 | H100: 김창욱 | I100: 발송완료 | J100: 42
A101: 45641.929 | B101: 45641 | C101: 20241215-000000049 | D101: 스탑북 | E101: 20241215220656AB02 | F101: 러브데이북 (러브데이북_280_210_기성커버 / 280X210 | 기본금박(무료) | 없음 | 38p | 퓨어아이보리(기본금박)) | G101: 1 | H101: 김창욱 | I101: 발송완료 | J101: 40
A102: 45641.98 | B102: 45641 | C102: 20241215-000000053 | D102: 스탑북 | E102: 2024121523224270D4 | F102: 러브데이북 (러브데이북_280_210_기성커버 / 280X210 | 기본금박(무료) | 없음 | 38p | 모던그레이(기본금박)) | G102: 1 | H102: 김장헌 | I102: 발송완료 | J102: 60
A103: 45642.019 | B103: 45642 | C103: 20241216-000000003 | D103: 스탑북 | E103: 20241216002223235E | F103: 레더북 (레더북_210_280_원단커버 포토북 / 210X280|원단커버_실제본|없음|38p | 커버타이틀 1 | 딥그린) | G103: 1 | H103: 이보라 | I103: 발송완료 | J103: 60
A104: 45642.088 | B104: 45642 | C104: 20241216-000000019 | D104: 스탑북 | E104: 202412160147569584 | F104: 레더북 (레더북_210_280_원단커버 포토북 / 210X280|원단커버_실제본|없음|38p | 커버타이틀 1 | 딥그린) | G104: 1 | H104: 이인규 | I104: 발송완료 | J104: 60
A105: 45642.088 | B105: 45642 | C105: 20241216-000000020 | D105: 스탑북 | E105: 202412160147569584 | F105: 레더북 (레더북_210_280_원단커버 포토북 / 210X280 | 원단커버_실제본 | 없음 | 38p | 커버타이틀 1 | 로얄와인) | G105: 1 | H105: 이인규 | I105: 발송완료 | J105: 60
A106: 45642.088 | B106: 45642 | C106: 20241216-000000021 | D106: 스탑북 | E106: 202412160147569584 | F106: 레더북 (레더북_210_280_원단커버 포토북 / 210X280 | 원단커버_실제본 | 없음 | 38p | 커버타이틀 1 | 다크네이비) | G106: 1 | H106: 이인규 | I106: 발송완료 | J106: 60
A107: 45642.088 | B107: 45642 | C107: 20241216-000000022 | D107: 스탑북 | E107: 202412160147569584 | F107: 레더북 (레더북_210_280_원단커버 포토북 / 210X280 | 원단커버_실제본 | 없음 | 38p | 커버타이틀 1 | 로얄와인) | G107: 1 | H107: 이인규 | I107: 발송완료 | J107: 56
... A111: 45643.491 | B111: 45643 | C111: 20241217-000000036 | D111: 스탑북 | E111: 202412171139070B22 | F111: 레더북 (레더북_210_280_원단커버 포토북 / 210X280 | 원단커버_실제본 | 없음 | 38p | 커버타이틀 1 | 다크네이비) | G111: 5 | H111: 김선화 | I111: 발송완료 | J111: 60
A112: 45643.579 | B112: 45643 | C112: 20241217-000000073 | D112: 스탑북 | E112: 2.0241217e+273 | F112: 드림클래스_가로타입_276_197 (포토그랩스_276_197_기성 원단커버(가변 스티커) / 276X197 | 하드커버 | 없음 | 48p) | G112: 1 | H112: 김진묵 | I112: 발송완료 | J112: 60
A113: 45643.579 | B113: 45643 | C113: 20241217-000000074 | D113: 스탑북 | E113: 202412171330406098 | F113: 드림클래스_가로타입_276_197 (포토그랩스_276_197_기성 원단커버(가변 스티커) / 276X197 | 하드커버 | 없음 | 48p) | G113: 1 | H113: 김진묵 | I113: 발송완료 | J113: 60
A114: 45643.579 | B114: 45643 | C114: 20241217-000000075 | D114: 스탑북 | E114: 202412171329444538 | F114: 드림클래스_가로타입_276_197 (포토그랩스_276_197_기성 원단커버(가변 스티커) / 276X197 | 하드커버 | 없음 | 48p) | G114: 1 | H114: 김진묵 | I114: 발송완료 | J114: 60
A115: 45643.579 | B115: 45643 | C115: 20241217-000000076 | D115: 스탑북 | E115: 2024121713285121FD | F115: 드림클래스_가로타입_276_197 (포토그랩스_276_197_기성 원단커버(가변 스티커) / 276X197 | 하드커버 | 없음 | 48p) | G115: 1 | H115: 김진묵 | I115: 발송완료 | J115: 60
A116: 45643.579 | B116: 45643 | C116: 20241217-000000077 | D116: 스탑북 | E116: 20241217132743EE2C | F116: 드림클래스_가로타입_276_197 (포토그랩스_276_197_기성 원단커버(가변 스티커) / 276X197 | 하드커버 | 없음 | 48p) | G116: 1 | H116: 김진묵 | I116: 발송완료 | J116: 60
A117: 45643.579 | B117: 45643 | C117: 20241217-000000078 | D117: 스탑북 | E117: 202412171326514C89 | F117: 드림클래스_가로타입_276_197 (포토그랩스_276_197_기성 원단커버(가변 스티커) / 276X197 | 하드커버 | 없음 | 48p) | G117: 1 | H117: 김진묵 | I117: 발송완료 | J117: 60
A118: 45643.579 | B118: 45643 | C118: 20241217-000000079 | D118: 스탑북 | E118: 20241217132553BEC1 | F118: 드림클래스_가로타입_276_197 (포토그랩스_276_197_기성 원단커버(가변 스티커) / 276X197 | 하드커버 | 없음 | 48p) | G118: 1 | H118: 김진묵 | I118: 발송완료 | J118: 60
A119: 45643.58 | B119: 45643 | C119: 20241217-000000080 | D119: 스탑북 | E119: 20241217132427E20F | F119: 드림클래스_가로타입_276_197 (포토그랩스_276_197_기성 원단커버(가변 스티커) / 276X197 | 하드커버 | 없음 | 48p) | G119: 1 | H119: 김진묵 | I119: 발송완료 | J119: 60
A120: 45643.58 | B120: 45643 | C120: 20241217-000000081 | D120: 스탑북 | E120: 20241217132317B345 | F120: 드림클래스_가로타입_276_197 (포토그랩스_276_197_기성 원단커버(가변 스티커) / 276X197 | 하드커버 | 없음 | 48p) | G120: 1 | H120: 김진묵 | I120: 발송완료 | J120: 60
A121: 45643.58 | B121: 45643 | C121: 20241217-000000082 | D121: 스탑북 | E121: 202412171322117870 | F121: 드림클래스_가로타입_276_197 (포토그랩스_276_197_기성 원단커버(가변 스티커) / 276X197 | 하드커버 | 없음 | 48p) | G121: 1 | H121: 김진묵 | I121: 발송완료 | J121: 60
A122: 45643.58 | B122: 45643 | C122: 20241217-000000083 | D122: 스탑북 | E122: 202412171312312F9B | F122: 드림클래스_가로타입_276_197 (포토그랩스_276_197_기성 원단커버(가변 스티커) / 276X197 | 하드커버 | 없음 | 48p) | G122: 1 | H122: 김진묵 | I122: 발송완료 | J122: 60
A123: 45643.68 | B123: 45643 | C123: 20241217-000000132 | D123: 스탑북 | E123: 202412171613475EFB | F123: 레더북 (레더북_210_280_원단커버 포토북 / 210X280 | 원단커버_실제본 | 없음 | 38p | 커버타이틀 1 | 로얄와인) | G123: 12 | H123: 서지인 | I123: 발송완료 | J123: 40
...

Sheet 연간집계
A1: 2026 | B1: 구분 | C1: 판매상품명 | D1: 상품명 | E1: 상품명 | F1: 건수 | G1: 부수 | H1: 평균부수 | I1: 평균페이지 | J1: 비율 | K1: 소계 | L1: PC | N1: MO | Q1: 구분 | R1: 주문건수 | S1: 주문부수 | T1: 평균부수 | U1: 비율 | V1: PC | X1: MO
F2: =SUM(F3:F1179) -> 4504 | G2: =SUM(G3:G1179) -> 7925 | H2: =IFERROR(G2/F2,"") -> 1.7595471 | L2: =SUM(L3:L1179) -> 7044 | M2: =IFERROR($L2/($L2+$N2),"") -> 0.89300203 | N2: =SUM(N3:N1179) -> 844 | O2: =IFERROR($N2/($N2+$L2),"") -> 0.10699797 | Q2: =COUNTA(Q3:Q1179) -> 24 | R2: =SUM(R3:R1179) -> 4466 | S2: =SUM(S3:S1179) -> 7871 | T2: =IFERROR(S2/R2,"") -> 1.7624272 | V2: =SUM(V3:V1179) -> 7031 | W2: =IFERROR(V2/($V2+$X2),"") -> 0.89327913 | X2: =SUM(X3:X1179) -> 840 | Y2: =IFERROR(X2/($V2+$X2),"") -> 0.10672087 | AA2: =SUM(V2+X2) -> 7871
A3: 포토북 | B3: 스탠다드 | C3: 150*210 | D3: PCMS_150_210 (PCMS_150_210_소프트커버_무광 / 150x210 | 소프트커버무광 | 없음 | 22p) | E3: 스탠다드 포토북 6*8 (소프트/무광) | F3: =COUNTIFS(데이터!F:F,D3,데이터!$N:$N,$A$1) -> 51 | G3: =SUMIFS(데이터!G:G,데이터!F:F,D3,데이터!$N:$N,$A$1) -> 102 | H3: =IFERROR(G3/F3,0) -> 2 | I3: =IFERROR((SUMIFS(데이터!K:K,데이터!F:F,D3,데이터!$N:$N,$A$1))/F3,0) -> 38.352941 | J3: =IFERROR($G3/$G$2,"") -> 0.012870662 | K3: =SUM(G3:G6) -> 914 | L3: =IFERROR(SUMIFS(데이터!$G:$G,데이터!$F:$F,$D3,데이터!$N:$N,$A$1,데이터!$L:$L,L$1),"") -> 102 | M3: =IFERROR($L3/($L3+$N3),"") -> 1 | N3: =IFERROR(SUMIFS(데이터!$G:$G,데이터!$F:$F,$D3,데이터!$N:$N,$A$1,데이터!$L:$L,N$1),"") -> 0 | O3: =IFERROR($N3/($N3+$L3),"") -> 0 | Q3: =IFERROR(__xludf.DUMMYFUNCTION("iferror(SORT( UNIQUE( FILTER( '데이터'!$M:$M, '데이터'!$N:$N = $A$1, '데이터'!$M:$M <> """" ) ), 1, TRUE ),""-"")"),"01.여행 : 개인/가족") -> 01.여행 : 개인/가족 | R3: =IFERROR(COUNTIFS(데이터!$N:$N,$A$1,데이터!$M:$M,$Q3),"") -> 1613 | S3: =IFERROR(SUMIFS(데이터!$G:$G,데이터!$N:$N,$A$1,데이터!$M:$M,$Q3),"") -> 2128 | T3: =IFERROR(S3/R3,0) -> 1.3192808 | U3: =IFERROR(S3/(SUM($S$3:$S1179)),"") -> 0.27035955 | V3: =SUMIFS(데이터!$G:$G,데이터!$N:$N,$A$1,데이터!$M:$M,$Q3,데이터!$L:$L,$V$1) -> 1865 | W3: =IFERROR(V3/($V3+$X3),"") -> 0.87640977 | X3: =SUMIFS(데이터!$G:$G,데이터!$N:$N,$A$1,데이터!$M:$M,$Q3,데이터!$L:$L,$X$1) -> 263 | Y3: =IFERROR(X3/($V3+$X3),"") -> 0.12359023
D4: PCMS_150_210 (PCMS_150_210_소프트커버_유광 / 150x210 | 소프트커버유광 | 없음 | 22p) | E4: 스탠다드 포토북 6*8 (소프트/유광) | F4: =COUNTIFS(데이터!F:F,D4,데이터!$N:$N,$A$1) -> 18 | G4: =SUMIFS(데이터!G:G,데이터!F:F,D4,데이터!$N:$N,$A$1) -> 31 | H4: =IFERROR(G4/F4,0) -> 1.7222222 | I4: =IFERROR((SUMIFS(데이터!K:K,데이터!F:F,D4,데이터!$N:$N,$A$1))/F4,0) -> 34.333333 | J4: =IFERROR($G4/$G$2,"") -> 0.0039116719 | L4: =IFERROR(SUMIFS(데이터!$G:$G,데이터!$F:$F,$D4,데이터!$N:$N,$A$1,데이터!$L:$L,L$1),"") -> 31 | M4: =IFERROR($L4/($L4+$N4),"") -> 1 | N4: =IFERROR(SUMIFS(데이터!$G:$G,데이터!$F:$F,$D4,데이터!$N:$N,$A$1,데이터!$L:$L,N$1),"") -> 0 | O4: =IFERROR($N4/($N4+$L4),"") -> 0 | Q4: =IFERROR(__xludf.DUMMYFUNCTION("""COMPUTED_VALUE"""),"01.여행 : 단체/모임/친구") -> 01.여행 : 단체/모임/친구 | R4: =IFERROR(COUNTIFS(데이터!$N:$N,$A$1,데이터!$M:$M,$Q4),"") -> 331 | S4: =IFERROR(SUMIFS(데이터!$G:$G,데이터!$N:$N,$A$1,데이터!$M:$M,$Q4),"") -> 735 | T4: =IFERROR(S4/R4,0) -> 2.2205438 | U4: =IFERROR(S4/(SUM($S$3:$S1180)),"") -> 0.093380765 | V4: =SUMIFS(데이터!$G:$G,데이터!$N:$N,$A$1,데이터!$M:$M,$Q4,데이터!$L:$L,$V$1) -> 629 | W4: =IFERROR(V4/($V4+$X4),"") -> 0.85578231 | X4: =SUMIFS(데이터!$G:$G,데이터!$N:$N,$A$1,데이터!$M:$M,$Q4,데이터!$L:$L,$X$1) -> 106 | Y4: =IFERROR(X4/($V4+$X4),"") -> 0.14421769
D5: PCMS_150_210 (PCMS_150_210_하드커버_무광 / 150x210 | 하드커버무광 | 없음 | 22p) | E5: 스탠다드 포토북 6*8 (하드/무광) | F5: =COUNTIFS(데이터!F:F,D5,데이터!$N:$N,$A$1) -> 451 | G5: =SUMIFS(데이터!G:G,데이터!F:F,D5,데이터!$N:$N,$A$1) -> 702 | H5: =IFERROR(G5/F5,0) -> 1.556541 | I5: =IFERROR((SUMIFS(데이터!K:K,데이터!F:F,D5,데이터!$N:$N,$A$1))/F5,0) -> 37.911308 | J5: =IFERROR($G5/$G$2,"") -> 0.088580442 | L5: =IFERROR(SUMIFS(데이터!$G:$G,데이터!$F:$F,$D5,데이터!$N:$N,$A$1,데이터!$L:$L,L$1),"") -> 696 | M5: =IFERROR($L5/($L5+$N5),"") -> 1 | N5: =IFERROR(SUMIFS(데이터!$G:$G,데이터!$F:$F,$D5,데이터!$N:$N,$A$1,데이터!$L:$L,N$1),"") -> 0 | O5: =IFERROR($N5/($N5+$L5),"") -> 0 | Q5: =IFERROR(__xludf.DUMMYFUNCTION("""COMPUTED_VALUE"""),"01.여행 : 커플") -> 01.여행 : 커플 | R5: =IFERROR(COUNTIFS(데이터!$N:$N,$A$1,데이터!$M:$M,$Q5),"") -> 105 | S5: =IFERROR(SUMIFS(데이터!$G:$G,데이터!$N:$N,$A$1,데이터!$M:$M,$Q5),"") -> 119 | T5: =IFERROR(S5/R5,0) -> 1.1333333 | U5: =IFERROR(S5/(SUM($S$3:$S1181)),"") -> 0.01511879 | V5: =SUMIFS(데이터!$G:$G,데이터!$N:$N,$A$1,데이터!$M:$M,$Q5,데이터!$L:$L,$V$1) -> 104 | W5: =IFERROR(V5/($V5+$X5),"") -> 0.87394958 | X5: =SUMIFS(데이터!$G:$G,데이터!$N:$N,$A$1,데이터!$M:$M,$Q5,데이터!$L:$L,$X$1) -> 15 | Y5: =IFERROR(X5/($V5+$X5),"") -> 0.12605042
D6: PCMS_150_210 (PCMS_150_210_하드커버_유광 / 150x210 | 하드커버유광 | 없음 | 22p) | E6: 스탠다드 포토북 6*8 (하드/유광) | F6: =COUNTIFS(데이터!F:F,D6,데이터!$N:$N,$A$1) -> 46 | G6: =SUMIFS(데이터!G:G,데이터!F:F,D6,데이터!$N:$N,$A$1) -> 79 | H6: =IFERROR(G6/F6,0) -> 1.7173913 | I6: =IFERROR((SUMIFS(데이터!K:K,데이터!F:F,D6,데이터!$N:$N,$A$1))/F6,0) -> 45.304348 | J6: =IFERROR($G6/$G$2,"") -> 0.0099684543 | L6: =IFERROR(SUMIFS(데이터!$G:$G,데이터!$F:$F,$D6,데이터!$N:$N,$A$1,데이터!$L:$L,L$1),"") -> 79 | M6: =IFERROR($L6/($L6+$N6),"") -> 1 | N6: =IFERROR(SUMIFS(데이터!$G:$G,데이터!$F:$F,$D6,데이터!$N:$N,$A$1,데이터!$L:$L,N$1),"") -> 0 | O6: =IFERROR($N6/($N6+$L6),"") -> 0 | Q6: =IFERROR(__xludf.DUMMYFUNCTION("""COMPUTED_VALUE"""),"02.일상 : 개인/가족") -> 02.일상 : 개인/가족 | R6: =IFERROR(COUNTIFS(데이터!$N:$N,$A$1,데이터!$M:$M,$Q6),"") -> 254 | S6: =IFERROR(SUMIFS(데이터!$G:$G,데이터!$N:$N,$A$1,데이터!$M:$M,$Q6),"") -> 369 | T6: =IFERROR(S6/R6,0) -> 1.4527559 | U6: =IFERROR(S6/(SUM($S$3:$S1182)),"") -> 0.046880955 | V6: =SUMIFS(데이터!$G:$G,데이터!$N:$N,$A$1,데이터!$M:$M,$Q6,데이터!$L:$L,$V$1) -> 337 | W6: =IFERROR(V6/($V6+$X6),"") -> 0.91327913 | X6: =SUMIFS(데이터!$G:$G,데이터!$N:$N,$A$1,데이터!$M:$M,$Q6,데이터!$L:$L,$X$1) -> 32 | Y6: =IFERROR(X6/($V6+$X6),"") -> 0.086720867
C7: 197*278 | D7: PCMS_197_278 (PCMS_197_278_소프트커버_무광 / 197x278 | 소프트커버무광 | 없음 | 22p) | E7: 스탠다드 포토북 8*11 (소프트/무광) | F7: =COUNTIFS(데이터!F:F,D7,데이터!$N:$N,$A$1) -> 42 | G7: =SUMIFS(데이터!G:G,데이터!F:F,D7,데이터!$N:$N,$A$1) -> 66 | H7: =IFERROR(G7/F7,0) -> 1.5714286 | I7: =IFERROR((SUMIFS(데이터!K:K,데이터!F:F,D7,데이터!$N:$N,$A$1))/F7,0) -> 46.857143 | J7: =IFERROR($G7/$G$2,"") -> 0.0083280757 | K7: =SUM(G7:G10) -> 640 | L7: =IFERROR(SUMIFS(데이터!$G:$G,데이터!$F:$F,$D7,데이터!$N:$N,$A$1,데이터!$L:$L,L$1),"") -> 66 | M7: =IFERROR($L7/($L7+$N7),"") -> 1 | N7: =IFERROR(SUMIFS(데이터!$G:$G,데이터!$F:$F,$D7,데이터!$N:$N,$A$1,데이터!$L:$L,N$1),"") -> 0 | O7: =IFERROR($N7/($N7+$L7),"") -> 0 | Q7: =IFERROR(__xludf.DUMMYFUNCTION("""COMPUTED_VALUE"""),"02.일상 : 베이비/성장") -> 02.일상 : 베이비/성장 | R7: =IFERROR(COUNTIFS(데이터!$N:$N,$A$1,데이터!$M:$M,$Q7),"") -> 581 | S7: =IFERROR(SUMIFS(데이터!$G:$G,데이터!$N:$N,$A$1,데이터!$M:$M,$Q7),"") -> 801 | T7: =IFERROR(S7/R7,0) -> 1.3786575 | U7: =IFERROR(S7/(SUM($S$3:$S1183)),"") -> 0.10176598 | V7: =SUMIFS(데이터!$G:$G,데이터!$N:$N,$A$1,데이터!$M:$M,$Q7,데이터!$L:$L,$V$1) -> 651 | W7: =IFERROR(V7/($V7+$X7),"") -> 0.81273408 | X7: =SUMIFS(데이터!$G:$G,데이터!$N:$N,$A$1,데이터!$M:$M,$Q7,데이터!$L:$L,$X$1) -> 150 | Y7: =IFERROR(X7/($V7+$X7),"") -> 0.18726592
D8: PCMS_197_278 (PCMS_197_278_소프트커버_유광 / 197x278 | 소프트커버유광 | 없음 | 22p) | E8: 스탠다드 포토북 8*11 (소프트/유광) | F8: =COUNTIFS(데이터!F:F,D8,데이터!$N:$N,$A$1) -> 19 | G8: =SUMIFS(데이터!G:G,데이터!F:F,D8,데이터!$N:$N,$A$1) -> 26 | H8: =IFERROR(G8/F8,0) -> 1.3684211 | I8: =IFERROR((SUMIFS(데이터!K:K,데이터!F:F,D8,데이터!$N:$N,$A$1))/F8,0) -> 46 | J8: =IFERROR($G8/$G$2,"") -> 0.0032807571 | L8: =IFERROR(SUMIFS(데이터!$G:$G,데이터!$F:$F,$D8,데이터!$N:$N,$A$1,데이터!$L:$L,L$1),"") -> 26 | M8: =IFERROR($L8/($L8+$N8),"") -> 1 | N8: =IFERROR(SUMIFS(데이터!$G:$G,데이터!$F:$F,$D8,데이터!$N:$N,$A$1,데이터!$L:$L,N$1),"") -> 0 | O8: =IFERROR($N8/($N8+$L8),"") -> 0 | Q8: =IFERROR(__xludf.DUMMYFUNCTION("""COMPUTED_VALUE"""),"02.일상 : 커플") -> 02.일상 : 커플 | R8: =IFERROR(COUNTIFS(데이터!$N:$N,$A$1,데이터!$M:$M,$Q8),"") -> 85 | S8: =IFERROR(SUMIFS(데이터!$G:$G,데이터!$N:$N,$A$1,데이터!$M:$M,$Q8),"") -> 95 | T8: =IFERROR(S8/R8,0) -> 1.1176471 | U8: =IFERROR(S8/(SUM($S$3:$S1184)),"") -> 0.012069623 | V8: =SUMIFS(데이터!$G:$G,데이터!$N:$N,$A$1,데이터!$M:$M,$Q8,데이터!$L:$L,$V$1) -> 70 | W8: =IFERROR(V8/($V8+$X8),"") -> 0.73684211 | X8: =SUMIFS(데이터!$G:$G,데이터!$N:$N,$A$1,데이터!$M:$M,$Q8,데이터!$L:$L,$X$1) -> 25 | Y8: =IFERROR(X8/($V8+$X8),"") -> 0.26315789
D9: PCMS_197_278 (PCMS_197_278_하드커버_무광 / 197x278 | 하드커버무광 | 없음 | 22p) | E9: 스탠다드 포토북 8*11 (하드/무광) | F9: =COUNTIFS(데이터!F:F,D9,데이터!$N:$N,$A$1) -> 290 | G9: =SUMIFS(데이터!G:G,데이터!F:F,D9,데이터!$N:$N,$A$1) -> 381 | H9: =IFERROR(G9/F9,0) -> 1.3137931 | I9: =IFERROR((SUMIFS(데이터!K:K,데이터!F:F,D9,데이터!$N:$N,$A$1))/F9,0) -> 40.737931 | J9: =IFERROR($G9/$G$2,"") -> 0.04807571 | L9: =IFERROR(SUMIFS(데이터!$G:$G,데이터!$F:$F,$D9,데이터!$N:$N,$A$1,데이터!$L:$L,L$1),"") -> 378 | M9: =IFERROR($L9/($L9+$N9),"") -> 1 | N9: =IFERROR(SUMIFS(데이터!$G:$G,데이터!$F:$F,$D9,데이터!$N:$N,$A$1,데이터!$L:$L,N$1),"") -> 0 | O9: =IFERROR($N9/($N9+$L9),"") -> 0 | Q9: =IFERROR(__xludf.DUMMYFUNCTION("""COMPUTED_VALUE"""),"03.행사/기념 : 개인/가족") -> 03.행사/기념 : 개인/가족 | R9: =IFERROR(COUNTIFS(데이터!$N:$N,$A$1,데이터!$M:$M,$Q9),"") -> 194 | S9: =IFERROR(SUMIFS(데이터!$G:$G,데이터!$N:$N,$A$1,데이터!$M:$M,$Q9),"") -> 283 | T9: =IFERROR(S9/R9,0) -> 1.4587629 | U9: =IFERROR(S9/(SUM($S$3:$S1185)),"") -> 0.035954771 | V9: =SUMIFS(데이터!$G:$G,데이터!$N:$N,$A$1,데이터!$M:$M,$Q9,데이터!$L:$L,$V$1) -> 252 | W9: =IFERROR(V9/($V9+$X9),"") -> 0.89045936 | X9: =SUMIFS(데이터!$G:$G,데이터!$N:$N,$A$1,데이터!$M:$M,$Q9,데이터!$L:$L,$X$1) -> 31 | Y9: =IFERROR(X9/($V9+$X9),"") -> 0.10954064
D10: PCMS_197_278 (PCMS_197_278_하드커버_유광 / 197x278 | 하드커버유광 | 없음 | 22p) | E10: 스탠다드 포토북 8*11 (하드/유광) | F10: =COUNTIFS(데이터!F:F,D10,데이터!$N:$N,$A$1) -> 89 | G10: =SUMIFS(데이터!G:G,데이터!F:F,D10,데이터!$N:$N,$A$1) -> 167 | H10: =IFERROR(G10/F10,0) -> 1.8764045 | I10: =IFERROR((SUMIFS(데이터!K:K,데이터!F:F,D10,데이터!$N:$N,$A$1))/F10,0) -> 43.101124 | J10: =IFERROR($G10/$G$2,"") -> 0.021072555 | L10: =IFERROR(SUMIFS(데이터!$G:$G,데이터!$F:$F,$D10,데이터!$N:$N,$A$1,데이터!$L:$L,L$1),"") -> 167 | M10: =IFERROR($L10/($L10+$N10),"") -> 1 | N10: =IFERROR(SUMIFS(데이터!$G:$G,데이터!$F:$F,$D10,데이터!$N:$N,$A$1,데이터!$L:$L,N$1),"") -> 0 | O10: =IFERROR($N10/($N10+$L10),"") -> 0 | Q10: =IFERROR(__xludf.DUMMYFUNCTION("""COMPUTED_VALUE"""),"03.행사/기념 : 기업/기관/단체") -> 03.행사/기념 : 기업/기관/단체 | R10: =IFERROR(COUNTIFS(데이터!$N:$N,$A$1,데이터!$M:$M,$Q10),"") -> 146 | S10: =IFERROR(SUMIFS(데이터!$G:$G,데이터!$N:$N,$A$1,데이터!$M:$M,$Q10),"") -> 866 | T10: =IFERROR(S10/R10,0) -> 5.9315068 | U10: =IFERROR(S10/(SUM($S$3:$S1186)),"") -> 0.11002414 | V10: =SUMIFS(데이터!$G:$G,데이터!$N:$N,$A$1,데이터!$M:$M,$Q10,데이터!$L:$L,$V$1) -> 846 | W10: =IFERROR(V10/($V10+$X10),"") -> 0.97690531 | X10: =SUMIFS(데이터!$G:$G,데이터!$N:$N,$A$1,데이터!$M:$M,$Q10,데이터!$L:$L,$X$1) -> 20 | Y10: =IFERROR(X10/($V10+$X10),"") -> 0.023094688
C11: 198*198 | D11: PCMS_198_198 (PCMS_198_198_소프트커버_무광 / 198x198 | 소프트커버무광 | 없음 | 22p) | E11: 스탠다드 포토북 8*8 (소프트/무광) | F11: =COUNTIFS(데이터!F:F,D11,데이터!$N:$N,$A$1) -> 47 | G11: =SUMIFS(데이터!G:G,데이터!F:F,D11,데이터!$N:$N,$A$1) -> 83 | H11: =IFERROR(G11/F11,0) -> 1.7659574 | I11: =IFERROR((SUMIFS(데이터!K:K,데이터!F:F,D11,데이터!$N:$N,$A$1))/F11,0) -> 52.893617 | J11: =IFERROR($G11/$G$2,"") -> 0.010473186 | K11: =SUM(G11:G14) -> 469 | L11: =IFERROR(SUMIFS(데이터!$G:$G,데이터!$F:$F,$D11,데이터!$N:$N,$A$1,데이터!$L:$L,L$1),"") -> 83 | M11: =IFERROR($L11/($L11+$N11),"") -> 1 | N11: =IFERROR(SUMIFS(데이터!$G:$G,데이터!$F:$F,$D11,데이터!$N:$N,$A$1,데이터!$L:$L,N$1),"") -> 0 | O11: =IFERROR($N11/($N11+$L11),"") -> 0 | Q11: =IFERROR(__xludf.DUMMYFUNCTION("""COMPUTED_VALUE"""),"03.행사/기념 : 베이비") -> 03.행사/기념 : 베이비 | R11: =IFERROR(COUNTIFS(데이터!$N:$N,$A$1,데이터!$M:$M,$Q11),"") -> 61 | S11: =IFERROR(SUMIFS(데이터!$G:$G,데이터!$N:$N,$A$1,데이터!$M:$M,$Q11),"") -> 100 | T11: =IFERROR(S11/R11,0) -> 1.6393443 | U11: =IFERROR(S11/(SUM($S$3:$S1187)),"") -> 0.012704866 | V11: =SUMIFS(데이터!$G:$G,데이터!$N:$N,$A$1,데이터!$M:$M,$Q11,데이터!$L:$L,$V$1) -> 94 | W11: =IFERROR(V11/($V11+$X11),"") -> 0.94 | X11: =SUMIFS(데이터!$G:$G,데이터!$N:$N,$A$1,데이터!$M:$M,$Q11,데이터!$L:$L,$X$1) -> 6 | Y11: =IFERROR(X11/($V11+$X11),"") -> 0.06
D12: PCMS_198_198 (PCMS_198_198_소프트커버_유광 / 198x198 | 소프트커버유광 | 없음 | 22p) | E12: 스탠다드 포토북 8*8 (소프트/유광) | F12: =COUNTIFS(데이터!F:F,D12,데이터!$N:$N,$A$1) -> 11 | G12: =SUMIFS(데이터!G:G,데이터!F:F,D12,데이터!$N:$N,$A$1) -> 16 | H12: =IFERROR(G12/F12,0) -> 1.4545455 | I12: =IFERROR((SUMIFS(데이터!K:K,데이터!F:F,D12,데이터!$N:$N,$A$1))/F12,0) -> 54 | J12: =IFERROR($G12/$G$2,"") -> 0.0020189274 | L12: =IFERROR(SUMIFS(데이터!$G:$G,데이터!$F:$F,$D12,데이터!$N:$N,$A$1,데이터!$L:$L,L$1),"") -> 16 | M12: =IFERROR($L12/($L12+$N12),"") -> 1 | N12: =IFERROR(SUMIFS(데이터!$G:$G,데이터!$F:$F,$D12,데이터!$N:$N,$A$1,데이터!$L:$L,N$1),"") -> 0 | O12: =IFERROR($N12/($N12+$L12),"") -> 0 | Q12: =IFERROR(__xludf.DUMMYFUNCTION("""COMPUTED_VALUE"""),"03.행사/기념 : 웨딩") -> 03.행사/기념 : 웨딩 | R12: =IFERROR(COUNTIFS(데이터!$N:$N,$A$1,데이터!$M:$M,$Q12),"") -> 87 | S12: =IFERROR(SUMIFS(데이터!$G:$G,데이터!$N:$N,$A$1,데이터!$M:$M,$Q12),"") -> 97 | T12: =IFERROR(S12/R12,0) -> 1.1149425 | U12: =IFERROR(S12/(SUM($S$3:$S1188)),"") -> 0.01232372 | V12: =SUMIFS(데이터!$G:$G,데이터!$N:$N,$A$1,데이터!$M:$M,$Q12,데이터!$L:$L,$V$1) -> 90 | W12: =IFERROR(V12/($V12+$X12),"") -> 0.92783505 | X12: =SUMIFS(데이터!$G:$G,데이터!$N:$N,$A$1,데이터!$M:$M,$Q12,데이터!$L:$L,$X$1) -> 7 | Y12: =IFERROR(X12/($V12+$X12),"") -> 0.072164948
D13: PCMS_198_198 (PCMS_198_198_하드커버_무광 / 198x198 | 하드커버무광 | 없음 | 22p) | E13: 스탠다드 포토북 8*8 (하드/무광) | F13: =COUNTIFS(데이터!F:F,D13,데이터!$N:$N,$A$1) -> 177 | G13: =SUMIFS(데이터!G:G,데이터!F:F,D13,데이터!$N:$N,$A$1) -> 282 | H13: =IFERROR(G13/F13,0) -> 1.5932203 | I13: =IFERROR((SUMIFS(데이터!K:K,데이터!F:F,D13,데이터!$N:$N,$A$1))/F13,0) -> 40.632768 | J13: =IFERROR($G13/$G$2,"") -> 0.035583596 | L13: =IFERROR(SUMIFS(데이터!$G:$G,데이터!$F:$F,$D13,데이터!$N:$N,$A$1,데이터!$L:$L,L$1),"") -> 282 | M13: =IFERROR($L13/($L13+$N13),"") -> 1 | N13: =IFERROR(SUMIFS(데이터!$G:$G,데이터!$F:$F,$D13,데이터!$N:$N,$A$1,데이터!$L:$L,N$1),"") -> 0 | O13: =IFERROR($N13/($N13+$L13),"") -> 0 | Q13: =IFERROR(__xludf.DUMMYFUNCTION("""COMPUTED_VALUE"""),"04.작품 : 개인") -> 04.작품 : 개인 | R13: =IFERROR(COUNTIFS(데이터!$N:$N,$A$1,데이터!$M:$M,$Q13),"") -> 110 | S13: =IFERROR(SUMIFS(데이터!$G:$G,데이터!$N:$N,$A$1,데이터!$M:$M,$Q13),"") -> 341 | T13: =IFERROR(S13/R13,0) -> 3.1 | U13: =IFERROR(S13/(SUM($S$3:$S1189)),"") -> 0.043323593 | V13: =SUMIFS(데이터!$G:$G,데이터!$N:$N,$A$1,데이터!$M:$M,$Q13,데이터!$L:$L,$V$1) -> 297 | W13: =IFERROR(V13/($V13+$X13),"") -> 0.87096774 | X13: =SUMIFS(데이터!$G:$G,데이터!$N:$N,$A$1,데이터!$M:$M,$Q13,데이터!$L:$L,$X$1) -> 44 | Y13: =IFERROR(X13/($V13+$X13),"") -> 0.12903226
D14: PCMS_198_198 (PCMS_198_198_하드커버_유광 / 198x198 | 하드커버유광 | 없음 | 22p) | E14: 스탠다드 포토북 8*8 (하드/유광) | F14: =COUNTIFS(데이터!F:F,D14,데이터!$N:$N,$A$1) -> 62 | G14: =SUMIFS(데이터!G:G,데이터!F:F,D14,데이터!$N:$N,$A$1) -> 88 | H14: =IFERROR(G14/F14,0) -> 1.4193548 | I14: =IFERROR((SUMIFS(데이터!K:K,데이터!F:F,D14,데이터!$N:$N,$A$1))/F14,0) -> 32.258065 | J14: =IFERROR($G14/$G$2,"") -> 0.011104101 | L14: =IFERROR(SUMIFS(데이터!$G:$G,데이터!$F:$F,$D14,데이터!$N:$N,$A$1,데이터!$L:$L,L$1),"") -> 88 | M14: =IFERROR($L14/($L14+$N14),"") -> 1 | N14: =IFERROR(SUMIFS(데이터!$G:$G,데이터!$F:$F,$D14,데이터!$N:$N,$A$1,데이터!$L:$L,N$1),"") -> 0 | O14: =IFERROR($N14/($N14+$L14),"") -> 0 | Q14: =IFERROR(__xludf.DUMMYFUNCTION("""COMPUTED_VALUE"""),"04.작품 : 기업/기관/단체") -> 04.작품 : 기업/기관/단체 | R14: =IFERROR(COUNTIFS(데이터!$N:$N,$A$1,데이터!$M:$M,$Q14),"") -> 1 | S14: =IFERROR(SUMIFS(데이터!$G:$G,데이터!$N:$N,$A$1,데이터!$M:$M,$Q14),"") -> 1 | T14: =IFERROR(S14/R14,0) -> 1 | U14: =IFERROR(S14/(SUM($S$3:$S1190)),"") -> 0.00012704866 | V14: =SUMIFS(데이터!$G:$G,데이터!$N:$N,$A$1,데이터!$M:$M,$Q14,데이터!$L:$L,$V$1) -> 1 | W14: =IFERROR(V14/($V14+$X14),"") -> 1 | X14: =SUMIFS(데이터!$G:$G,데이터!$N:$N,$A$1,데이터!$M:$M,$Q14,데이터!$L:$L,$X$1) -> 0 | Y14: =IFERROR(X14/($V14+$X14),"") -> 0
C15: 200*147 | D15: PCMS_200_147 (PCMS_200_147_소프트커버_무광 / 200x147 | 소프트커버무광 | 없음 | 22p) | E15: 스탠다드 포토북 8*6 (소프트/무광) | F15: =COUNTIFS(데이터!F:F,D15,데이터!$N:$N,$A$1) -> 16 | G15: =SUMIFS(데이터!G:G,데이터!F:F,D15,데이터!$N:$N,$A$1) -> 21 | H15: =IFERROR(G15/F15,0) -> 1.3125 | I15: =IFERROR((SUMIFS(데이터!K:K,데이터!F:F,D15,데이터!$N:$N,$A$1))/F15,0) -> 29.25 | J15: =IFERROR($G15/$G$2,"") -> 0.0026498423 | K15: =SUM(G15:G18) -> 157 | L15: =IFERROR(SUMIFS(데이터!$G:$G,데이터!$F:$F,$D15,데이터!$N:$N,$A$1,데이터!$L:$L,L$1),"") -> 21 | M15: =IFERROR($L15/($L15+$N15),"") -> 1 | N15: =IFERROR(SUMIFS(데이터!$G:$G,데이터!$F:$F,$D15,데이터!$N:$N,$A$1,데이터!$L:$L,N$1),"") -> 0 | O15: =IFERROR($N15/($N15+$L15),"") -> 0 | Q15: =IFERROR(__xludf.DUMMYFUNCTION("""COMPUTED_VALUE"""),"04.작품 : 학교") -> 04.작품 : 학교 | R15: =IFERROR(COUNTIFS(데이터!$N:$N,$A$1,데이터!$M:$M,$Q15),"") -> 14 | S15: =IFERROR(SUMIFS(데이터!$G:$G,데이터!$N:$N,$A$1,데이터!$M:$M,$Q15),"") -> 52 | T15: =IFERROR(S15/R15,0) -> 3.7142857 | U15: =IFERROR(S15/(SUM($S$3:$S1191)),"") -> 0.0066065303 | V15: =SUMIFS(데이터!$G:$G,데이터!$N:$N,$A$1,데이터!$M:$M,$Q15,데이터!$L:$L,$V$1) -> 52 | W15: =IFERROR(V15/($V15+$X15),"") -> 1 | X15: =SUMIFS(데이터!$G:$G,데이터!$N:$N,$A$1,데이터!$M:$M,$Q15,데이터!$L:$L,$X$1) -> 0 | Y15: =IFERROR(X15/($V15+$X15),"") -> 0
D16: PCMS_200_147 (PCMS_200_147_소프트커버_유광 / 200x147 | 소프트커버유광 | 없음 | 22p) | E16: 스탠다드 포토북 8*6 (소프트/유광) | F16: =COUNTIFS(데이터!F:F,D16,데이터!$N:$N,$A$1) -> 3 | G16: =SUMIFS(데이터!G:G,데이터!F:F,D16,데이터!$N:$N,$A$1) -> 3 | H16: =IFERROR(G16/F16,0) -> 1 | I16: =IFERROR((SUMIFS(데이터!K:K,데이터!F:F,D16,데이터!$N:$N,$A$1))/F16,0) -> 40 | J16: =IFERROR($G16/$G$2,"") -> 0.0003785489 | L16: =IFERROR(SUMIFS(데이터!$G:$G,데이터!$F:$F,$D16,데이터!$N:$N,$A$1,데이터!$L:$L,L$1),"") -> 3 | M16: =IFERROR($L16/($L16+$N16),"") -> 1 | N16: =IFERROR(SUMIFS(데이터!$G:$G,데이터!$F:$F,$D16,데이터!$N:$N,$A$1,데이터!$L:$L,N$1),"") -> 0 | O16: =IFERROR($N16/($N16+$L16),"") -> 0 | Q16: =IFERROR(__xludf.DUMMYFUNCTION("""COMPUTED_VALUE"""),"05.활동집 : 어린이집/유치원") -> 05.활동집 : 어린이집/유치원 | R16: =IFERROR(COUNTIFS(데이터!$N:$N,$A$1,데이터!$M:$M,$Q16),"") -> 128 | S16: =IFERROR(SUMIFS(데이터!$G:$G,데이터!$N:$N,$A$1,데이터!$M:$M,$Q16),"") -> 266 | T16: =IFERROR(S16/R16,0) -> 2.078125 | U16: =IFERROR(S16/(SUM($S$3:$S1192)),"") -> 0.033794943 | V16: =SUMIFS(데이터!$G:$G,데이터!$N:$N,$A$1,데이터!$M:$M,$Q16,데이터!$L:$L,$V$1) -> 266 | W16: =IFERROR(V16/($V16+$X16),"") -> 1 | X16: =SUMIFS(데이터!$G:$G,데이터!$N:$N,$A$1,데이터!$M:$M,$Q16,데이터!$L:$L,$X$1) -> 0 | Y16: =IFERROR(X16/($V16+$X16),"") -> 0
D17: PCMS_200_147 (PCMS_200_147_하드커버_무광 / 200x147 | 하드커버무광 | 없음 | 22p) | E17: 스탠다드 포토북 8*6 (하드/무광) | F17: =COUNTIFS(데이터!F:F,D17,데이터!$N:$N,$A$1) -> 61 | G17: =SUMIFS(데이터!G:G,데이터!F:F,D17,데이터!$N:$N,$A$1) -> 119 | H17: =IFERROR(G17/F17,0) -> 1.9508197 | I17: =IFERROR((SUMIFS(데이터!K:K,데이터!F:F,D17,데이터!$N:$N,$A$1))/F17,0) -> 40.327869 | J17: =IFERROR($G17/$G$2,"") -> 0.015015773 | L17: =IFERROR(SUMIFS(데이터!$G:$G,데이터!$F:$F,$D17,데이터!$N:$N,$A$1,데이터!$L:$L,L$1),"") -> 119 | M17: =IFERROR($L17/($L17+$N17),"") -> 1 | N17: =IFERROR(SUMIFS(데이터!$G:$G,데이터!$F:$F,$D17,데이터!$N:$N,$A$1,데이터!$L:$L,N$1),"") -> 0 | O17: =IFERROR($N17/($N17+$L17),"") -> 0 | Q17: =IFERROR(__xludf.DUMMYFUNCTION("""COMPUTED_VALUE"""),"05.활동집 : 학교") -> 05.활동집 : 학교 | R17: =IFERROR(COUNTIFS(데이터!$N:$N,$A$1,데이터!$M:$M,$Q17),"") -> 103 | S17: =IFERROR(SUMIFS(데이터!$G:$G,데이터!$N:$N,$A$1,데이터!$M:$M,$Q17),"") -> 190 | T17: =IFERROR(S17/R17,0) -> 1.8446602 | U17: =IFERROR(S17/(SUM($S$3:$S1193)),"") -> 0.024139245 | V17: =SUMIFS(데이터!$G:$G,데이터!$N:$N,$A$1,데이터!$M:$M,$Q17,데이터!$L:$L,$V$1) -> 178 | W17: =IFERROR(V17/($V17+$X17),"") -> 0.93684211 | X17: =SUMIFS(데이터!$G:$G,데이터!$N:$N,$A$1,데이터!$M:$M,$Q17,데이터!$L:$L,$X$1) -> 12 | Y17: =IFERROR(X17/($V17+$X17),"") -> 0.063157895
D18: PCMS_200_147 (PCMS_200_147_하드커버_유광 / 200x147 | 하드커버유광 | 없음 | 22p) | E18: 스탠다드 포토북 8*6 (하드/유광) | F18: =COUNTIFS(데이터!F:F,D18,데이터!$N:$N,$A$1) -> 14 | G18: =SUMIFS(데이터!G:G,데이터!F:F,D18,데이터!$N:$N,$A$1) -> 14 | H18: =IFERROR(G18/F18,0) -> 1 | I18: =IFERROR((SUMIFS(데이터!K:K,데이터!F:F,D18,데이터!$N:$N,$A$1))/F18,0) -> 27.428571 | J18: =IFERROR($G18/$G$2,"") -> 0.0017665615 | L18: =IFERROR(SUMIFS(데이터!$G:$G,데이터!$F:$F,$D18,데이터!$N:$N,$A$1,데이터!$L:$L,L$1),"") -> 14 | M18: =IFERROR($L18/($L18+$N18),"") -> 1 | N18: =IFERROR(SUMIFS(데이터!$G:$G,데이터!$F:$F,$D18,데이터!$N:$N,$A$1,데이터!$L:$L,N$1),"") -> 0 | O18: =IFERROR($N18/($N18+$L18),"") -> 0 | Q18: =IFERROR(__xludf.DUMMYFUNCTION("""COMPUTED_VALUE"""),"06.졸업 : 어린이집/유치원") -> 06.졸업 : 어린이집/유치원 | R18: =IFERROR(COUNTIFS(데이터!$N:$N,$A$1,데이터!$M:$M,$Q18),"") -> 282 | S18: =IFERROR(SUMIFS(데이터!$G:$G,데이터!$N:$N,$A$1,데이터!$M:$M,$Q18),"") -> 330 | T18: =IFERROR(S18/R18,0) -> 1.1702128 | U18: =IFERROR(S18/(SUM($S$3:$S1194)),"") -> 0.041926058 | V18: =SUMIFS(데이터!$G:$G,데이터!$N:$N,$A$1,데이터!$M:$M,$Q18,데이터!$L:$L,$V$1) -> 329 | W18: =IFERROR(V18/($V18+$X18),"") -> 0.9969697 | X18: =SUMIFS(데이터!$G:$G,데이터!$N:$N,$A$1,데이터!$M:$M,$Q18,데이터!$L:$L,$X$1) -> 1 | Y18: =IFERROR(X18/($V18+$X18),"") -> 0.003030303
C19: 270*200 | D19: PCMS_270_200 (PCMS_270_200_소프트커버_무광 / 270x200 | 소프트커버무광 | 없음 | 22p) | E19: 스탠다드 포토북 11*8 (소프트/무광) | F19: =COUNTIFS(데이터!F:F,D19,데이터!$N:$N,$A$1) -> 12 | G19: =SUMIFS(데이터!G:G,데이터!F:F,D19,데이터!$N:$N,$A$1) -> 14 | H19: =IFERROR(G19/F19,0) -> 1.1666667 | I19: =IFERROR((SUMIFS(데이터!K:K,데이터!F:F,D19,데이터!$N:$N,$A$1))/F19,0) -> 44.333333 | J19: =IFERROR($G19/$G$2,"") -> 0.0017665615 | K19: =SUM(G19:G22) -> 234 | L19: =IFERROR(SUMIFS(데이터!$G:$G,데이터!$F:$F,$D19,데이터!$N:$N,$A$1,데이터!$L:$L,L$1),"") -> 14 | M19: =IFERROR($L19/($L19+$N19),"") -> 1 | N19: =IFERROR(SUMIFS(데이터!$G:$G,데이터!$F:$F,$D19,데이터!$N:$N,$A$1,데이터!$L:$L,N$1),"") -> 0 | O19: =IFERROR($N19/($N19+$L19),"") -> 0 | Q19: =IFERROR(__xludf.DUMMYFUNCTION("""COMPUTED_VALUE"""),"06.졸업 : 학교") -> 06.졸업 : 학교 | R19: =IFERROR(COUNTIFS(데이터!$N:$N,$A$1,데이터!$M:$M,$Q19),"") -> 48 | S19: =IFERROR(SUMIFS(데이터!$G:$G,데이터!$N:$N,$A$1,데이터!$M:$M,$Q19),"") -> 252 | T19: =IFERROR(S19/R19,0) -> 5.25 | U19: =IFERROR(S19/(SUM($S$3:$S1195)),"") -> 0.032016262 | V19: =SUMIFS(데이터!$G:$G,데이터!$N:$N,$A$1,데이터!$M:$M,$Q19,데이터!$L:$L,$V$1) -> 250 | W19: =IFERROR(V19/($V19+$X19),"") -> 0.99206349 | X19: =SUMIFS(데이터!$G:$G,데이터!$N:$N,$A$1,데이터!$M:$M,$Q19,데이터!$L:$L,$X$1) -> 2 | Y19: =IFERROR(X19/($V19+$X19),"") -> 0.0079365079
D20: PCMS_270_200 (PCMS_270_200_소프트커버_유광 / 270x200 | 소프트커버유광 | 없음 | 22p) | E20: 스탠다드 포토북 11*8 (소프트/유광) | F20: =COUNTIFS(데이터!F:F,D20,데이터!$N:$N,$A$1) -> 4 | G20: =SUMIFS(데이터!G:G,데이터!F:F,D20,데이터!$N:$N,$A$1) -> 5 | H20: =IFERROR(G20/F20,0) -> 1.25 | I20: =IFERROR((SUMIFS(데이터!K:K,데이터!F:F,D20,데이터!$N:$N,$A$1))/F20,0) -> 50 | J20: =IFERROR($G20/$G$2,"") -> 0.00063091483 | L20: =IFERROR(SUMIFS(데이터!$G:$G,데이터!$F:$F,$D20,데이터!$N:$N,$A$1,데이터!$L:$L,L$1),"") -> 5 | M20: =IFERROR($L20/($L20+$N20),"") -> 1 | N20: =IFERROR(SUMIFS(데이터!$G:$G,데이터!$F:$F,$D20,데이터!$N:$N,$A$1,데이터!$L:$L,N$1),"") -> 0 | O20: =IFERROR($N20/($N20+$L20),"") -> 0 | Q20: =IFERROR(__xludf.DUMMYFUNCTION("""COMPUTED_VALUE"""),"07.종교") -> 07.종교 | R20: =IFERROR(COUNTIFS(데이터!$N:$N,$A$1,데이터!$M:$M,$Q20),"") -> 83 | S20: =IFERROR(SUMIFS(데이터!$G:$G,데이터!$N:$N,$A$1,데이터!$M:$M,$Q20),"") -> 191 | T20: =IFERROR(S20/R20,0) -> 2.3012048 | U20: =IFERROR(S20/(SUM($S$3:$S1196)),"") -> 0.024266294 | V20: =SUMIFS(데이터!$G:$G,데이터!$N:$N,$A$1,데이터!$M:$M,$Q20,데이터!$L:$L,$V$1) -> 183 | W20: =IFERROR(V20/($V20+$X20),"") -> 0.95811518 | X20: =SUMIFS(데이터!$G:$G,데이터!$N:$N,$A$1,데이터!$M:$M,$Q20,데이터!$L:$L,$X$1) -> 8 | Y20: =IFERROR(X20/($V20+$X20),"") -> 0.041884817
D21: PCMS_270_200 (PCMS_270_200_하드커버_무광 / 270x200 | 하드커버무광 | 없음 | 22p) | E21: 스탠다드 포토북 11*8 (하드/무광) | F21: =COUNTIFS(데이터!F:F,D21,데이터!$N:$N,$A$1) -> 75 | G21: =SUMIFS(데이터!G:G,데이터!F:F,D21,데이터!$N:$N,$A$1) -> 193 | H21: =IFERROR(G21/F21,0) -> 2.5733333 | I21: =IFERROR((SUMIFS(데이터!K:K,데이터!F:F,D21,데이터!$N:$N,$A$1))/F21,0) -> 37.226667 | J21: =IFERROR($G21/$G$2,"") -> 0.024353312 | L21: =IFERROR(SUMIFS(데이터!$G:$G,데이터!$F:$F,$D21,데이터!$N:$N,$A$1,데이터!$L:$L,L$1),"") -> 192 | M21: =IFERROR($L21/($L21+$N21),"") -> 1 | N21: =IFERROR(SUMIFS(데이터!$G:$G,데이터!$F:$F,$D21,데이터!$N:$N,$A$1,데이터!$L:$L,N$1),"") -> 0 | O21: =IFERROR($N21/($N21+$L21),"") -> 0 | Q21: =IFERROR(__xludf.DUMMYFUNCTION("""COMPUTED_VALUE"""),"08.굿즈") -> 08.굿즈 | R21: =IFERROR(COUNTIFS(데이터!$N:$N,$A$1,데이터!$M:$M,$Q21),"") -> 76 | S21: =IFERROR(SUMIFS(데이터!$G:$G,데이터!$N:$N,$A$1,데이터!$M:$M,$Q21),"") -> 227 | T21: =IFERROR(S21/R21,0) -> 2.9868421 | U21: =IFERROR(S21/(SUM($S$3:$S1197)),"") -> 0.028840046 | V21: =SUMIFS(데이터!$G:$G,데이터!$N:$N,$A$1,데이터!$M:$M,$Q21,데이터!$L:$L,$V$1) -> 144 | W21: =IFERROR(V21/($V21+$X21),"") -> 0.63436123 | X21: =SUMIFS(데이터!$G:$G,데이터!$N:$N,$A$1,데이터!$M:$M,$Q21,데이터!$L:$L,$X$1) -> 83 | Y21: =IFERROR(X21/($V21+$X21),"") -> 0.36563877
D22: PCMS_270_200 (PCMS_270_200_하드커버_유광 / 270x200 | 하드커버유광 | 없음 | 22p) | E22: 스탠다드 포토북 11*8 (하드/유광) | F22: =COUNTIFS(데이터!F:F,D22,데이터!$N:$N,$A$1) -> 20 | G22: =SUMIFS(데이터!G:G,데이터!F:F,D22,데이터!$N:$N,$A$1) -> 22 | H22: =IFERROR(G22/F22,0) -> 1.1 | I22: =IFERROR((SUMIFS(데이터!K:K,데이터!F:F,D22,데이터!$N:$N,$A$1))/F22,0) -> 44.4 | J22: =IFERROR($G22/$G$2,"") -> 0.0027760252 | L22: =IFERROR(SUMIFS(데이터!$G:$G,데이터!$F:$F,$D22,데이터!$N:$N,$A$1,데이터!$L:$L,L$1),"") -> 22 | M22: =IFERROR($L22/($L22+$N22),"") -> 1 | N22: =IFERROR(SUMIFS(데이터!$G:$G,데이터!$F:$F,$D22,데이터!$N:$N,$A$1,데이터!$L:$L,N$1),"") -> 0 | O22: =IFERROR($N22/($N22+$L22),"") -> 0 | Q22: =IFERROR(__xludf.DUMMYFUNCTION("""COMPUTED_VALUE"""),"09.반려") -> 09.반려 | R22: =IFERROR(COUNTIFS(데이터!$N:$N,$A$1,데이터!$M:$M,$Q22),"") -> 56 | S22: =IFERROR(SUMIFS(데이터!$G:$G,데이터!$N:$N,$A$1,데이터!$M:$M,$Q22),"") -> 159 | T22: =IFERROR(S22/R22,0) -> 2.8392857 | U22: =IFERROR(S22/(SUM($S$3:$S1198)),"") -> 0.020200737 | V22: =SUMIFS(데이터!$G:$G,데이터!$N:$N,$A$1,데이터!$M:$M,$Q22,데이터!$L:$L,$V$1) -> 135 | W22: =IFERROR(V22/($V22+$X22),"") -> 0.8490566 | X22: =SUMIFS(데이터!$G:$G,데이터!$N:$N,$A$1,데이터!$M:$M,$Q22,데이터!$L:$L,$X$1) -> 24 | Y22: =IFERROR(X22/($V22+$X22),"") -> 0.1509434
B23: 유니크 | C23: 레코드북 | D23: 레코드북 (레코드북_150_210_가변 하드커버+기성 소프트 자켓 커버_무광 / 150X210 | 하드커버 | 없음 | 56p | 쟈켓색상 1) | E23: 레코드북 150 | F23: =COUNTIFS(데이터!F:F,D23,데이터!$N:$N,$A$1) -> 30 | G23: =SUMIFS(데이터!G:G,데이터!F:F,D23,데이터!$N:$N,$A$1) -> 54 | H23: =IFERROR(G23/F23,0) -> 1.8 | I23: =IFERROR((SUMIFS(데이터!K:K,데이터!F:F,D23,데이터!$N:$N,$A$1))/F23,0) -> 67.533333 | J23: =IFERROR($G23/$G$2,"") -> 0.0068138801 | K23: =SUM(G23:G24) -> 82 | L23: =IFERROR(SUMIFS(데이터!$G:$G,데이터!$F:$F,$D23,데이터!$N:$N,$A$1,데이터!$L:$L,L$1),"") -> 54 | M23: =IFERROR($L23/($L23+$N23),"") -> 1 | N23: =IFERROR(SUMIFS(데이터!$G:$G,데이터!$F:$F,$D23,데이터!$N:$N,$A$1,데이터!$L:$L,N$1),"") -> 0 | O23: =IFERROR($N23/($N23+$L23),"") -> 0 | Q23: =IFERROR(__xludf.DUMMYFUNCTION("""COMPUTED_VALUE"""),"10.홍보 : 기업/기관/단체") -> 10.홍보 : 기업/기관/단체 | R23: =IFERROR(COUNTIFS(데이터!$N:$N,$A$1,데이터!$M:$M,$Q23),"") -> 18 | S23: =IFERROR(SUMIFS(데이터!$G:$G,데이터!$N:$N,$A$1,데이터!$M:$M,$Q23),"") -> 130 | T23: =IFERROR(S23/R23,0) -> 7.2222222 | U23: =IFERROR(S23/(SUM($S$3:$S1199)),"") -> 0.016516326 | V23: =SUMIFS(데이터!$G:$G,데이터!$N:$N,$A$1,데이터!$M:$M,$Q23,데이터!$L:$L,$V$1) -> 129 | W23: =IFERROR(V23/($V23+$X23),"") -> 0.99230769 | X23: =SUMIFS(데이터!$G:$G,데이터!$N:$N,$A$1,데이터!$M:$M,$Q23,데이터!$L:$L,$X$1) -> 1 | Y23: =IFERROR(X23/($V23+$X23),"") -> 0.0076923077
D24: 레코드북 (레코드북_198_198_가변 하드커버+기성 소프트 자켓 커버_무광 / 198X198 | 하드커버 | 없음 | 56p | 쟈켓색상 1) | E24: 레코드북 198 | F24: =COUNTIFS(데이터!F:F,D24,데이터!$N:$N,$A$1) -> 17 | G24: =SUMIFS(데이터!G:G,데이터!F:F,D24,데이터!$N:$N,$A$1) -> 28 | H24: =IFERROR(G24/F24,0) -> 1.6470588 | I24: =IFERROR((SUMIFS(데이터!K:K,데이터!F:F,D24,데이터!$N:$N,$A$1))/F24,0) -> 69.294118 | J24: =IFERROR($G24/$G$2,"") -> 0.003533123 | L24: =IFERROR(SUMIFS(데이터!$G:$G,데이터!$F:$F,$D24,데이터!$N:$N,$A$1,데이터!$L:$L,L$1),"") -> 28 | M24: =IFERROR($L24/($L24+$N24),"") -> 1 | N24: =IFERROR(SUMIFS(데이터!$G:$G,데이터!$F:$F,$D24,데이터!$N:$N,$A$1,데이터!$L:$L,N$1),"") -> 0 | O24: =IFERROR($N24/($N24+$L24),"") -> 0 | Q24: =IFERROR(__xludf.DUMMYFUNCTION("""COMPUTED_VALUE"""),"11.퇴임/취임") -> 11.퇴임/취임 | R24: =IFERROR(COUNTIFS(데이터!$N:$N,$A$1,데이터!$M:$M,$Q24),"") -> 24 | S24: =IFERROR(SUMIFS(데이터!$G:$G,데이터!$N:$N,$A$1,데이터!$M:$M,$Q24),"") -> 38 | T24: =IFERROR(S24/R24,0) -> 1.5833333 | U24: =IFERROR(S24/(SUM($S$3:$S1200)),"") -> 0.0048278491 | V24: =SUMIFS(데이터!$G:$G,데이터!$N:$N,$A$1,데이터!$M:$M,$Q24,데이터!$L:$L,$V$1) -> 36 | W24: =IFERROR(V24/($V24+$X24),"") -> 0.94736842 | X24: =SUMIFS(데이터!$G:$G,데이터!$N:$N,$A$1,데이터!$M:$M,$Q24,데이터!$L:$L,$X$1) -> 2 | Y24: =IFERROR(X24/($V24+$X24),"") -> 0.052631579
C25: 마이트립북 | D25: 마이트립북 (마이트립북_150_210_하드커버_무광_린넨텍스트 / 150X210 | 하드커버 | 없음 | 50p) | E25: 마이트립북 150 | F25: =COUNTIFS(데이터!F:F,D25,데이터!$N:$N,$A$1) -> 52 | G25: =SUMIFS(데이터!G:G,데이터!F:F,D25,데이터!$N:$N,$A$1) -> 74 | H25: =IFERROR(G25/F25,0) -> 1.4230769 | I25: =IFERROR((SUMIFS(데이터!K:K,데이터!F:F,D25,데이터!$N:$N,$A$1))/F25,0) -> 65.461538 | J25: =IFERROR($G25/$G$2,"") -> 0.0093375394 | K25: =SUM(G25:G26) -> 123 | L25: =IFERROR(SUMIFS(데이터!$G:$G,데이터!$F:$F,$D25,데이터!$N:$N,$A$1,데이터!$L:$L,L$1),"") -> 74 | M25: =IFERROR($L25/($L25+$N25),"") -> 1 | N25: =IFERROR(SUMIFS(데이터!$G:$G,데이터!$F:$F,$D25,데이터!$N:$N,$A$1,데이터!$L:$L,N$1),"") -> 0 | O25: =IFERROR($N25/($N25+$L25),"") -> 0 | Q25: =IFERROR(__xludf.DUMMYFUNCTION("""COMPUTED_VALUE"""),"12.증명사진") -> 12.증명사진 | R25: =IFERROR(COUNTIFS(데이터!$N:$N,$A$1,데이터!$M:$M,$Q25),"") -> 55 | S25: =IFERROR(SUMIFS(데이터!$G:$G,데이터!$N:$N,$A$1,데이터!$M:$M,$Q25),"") -> 66 | T25: =IFERROR(S25/R25,0) -> 1.2 | U25: =IFERROR(S25/(SUM($S$3:$S1201)),"") -> 0.0083852115 | V25: =SUMIFS(데이터!$G:$G,데이터!$N:$N,$A$1,데이터!$M:$M,$Q25,데이터!$L:$L,$V$1) -> 66 | W25: =IFERROR(V25/($V25+$X25),"") -> 1 | X25: =SUMIFS(데이터!$G:$G,데이터!$N:$N,$A$1,데이터!$M:$M,$Q25,데이터!$L:$L,$X$1) -> 0 | Y25: =IFERROR(X25/($V25+$X25),"") -> 0
D26: 마이트립북 (마이트립북_198_198_하드커버_무광_린넨텍스트 / 198X198 | 하드커버 | 없음 | 50p) | E26: 마이트립북 198 | F26: =COUNTIFS(데이터!F:F,D26,데이터!$N:$N,$A$1) -> 34 | G26: =SUMIFS(데이터!G:G,데이터!F:F,D26,데이터!$N:$N,$A$1) -> 49 | H26: =IFERROR(G26/F26,0) -> 1.4411765 | I26: =IFERROR((SUMIFS(데이터!K:K,데이터!F:F,D26,데이터!$N:$N,$A$1))/F26,0) -> 65.882353 | J26: =IFERROR($G26/$G$2,"") -> 0.0061829653 | L26: =IFERROR(SUMIFS(데이터!$G:$G,데이터!$F:$F,$D26,데이터!$N:$N,$A$1,데이터!$L:$L,L$1),"") -> 49 | M26: =IFERROR($L26/($L26+$N26),"") -> 1 | N26: =IFERROR(SUMIFS(데이터!$G:$G,데이터!$F:$F,$D26,데이터!$N:$N,$A$1,데이터!$L:$L,N$1),"") -> 0 | O26: =IFERROR($N26/($N26+$L26),"") -> 0 | Q26: =IFERROR(__xludf.DUMMYFUNCTION("""COMPUTED_VALUE"""),"13.기타") -> 13.기타 | R26: =IFERROR(COUNTIFS(데이터!$N:$N,$A$1,데이터!$M:$M,$Q26),"") -> 11 | S26: =IFERROR(SUMIFS(데이터!$G:$G,데이터!$N:$N,$A$1,데이터!$M:$M,$Q26),"") -> 35 | T26: =IFERROR(S26/R26,0) -> 3.1818182 | U26: =IFERROR(S26/(SUM($S$3:$S1202)),"") -> 0.0044467031 | V26: =SUMIFS(데이터!$G:$G,데이터!$N:$N,$A$1,데이터!$M:$M,$Q26,데이터!$L:$L,$V$1) -> 27 | W26: =IFERROR(V26/($V26+$X26),"") -> 0.77142857 | X26: =SUMIFS(데이터!$G:$G,데이터!$N:$N,$A$1,데이터!$M:$M,$Q26,데이터!$L:$L,$X$1) -> 8 | Y26: =IFERROR(X26/($V26+$X26),"") -> 0.22857143
C27: 메모리북 | D27: 메모리북 (가족북(메모리북)_150_210_기성하드+가변 띠지_무광 / 150X210 | 하드커버 | 없음 | 46p) | E27: 메모리북 | F27: =COUNTIFS(데이터!F:F,D27,데이터!$N:$N,$A$1) -> 81 | G27: =SUMIFS(데이터!G:G,데이터!F:F,D27,데이터!$N:$N,$A$1) -> 101 | H27: =IFERROR(G27/F27,0) -> 1.2469136 | I27: =IFERROR((SUMIFS(데이터!K:K,데이터!F:F,D27,데이터!$N:$N,$A$1))/F27,0) -> 56.518519 | J27: =IFERROR($G27/$G$2,"") -> 0.012744479 | K27: =G27 -> 101 | L27: =IFERROR(SUMIFS(데이터!$G:$G,데이터!$F:$F,$D27,데이터!$N:$N,$A$1,데이터!$L:$L,L$1),"") -> 98 | M27: =IFERROR($L27/($L27+$N27),"") -> 1 | N27: =IFERROR(SUMIFS(데이터!$G:$G,데이터!$F:$F,$D27,데이터!$N:$N,$A$1,데이터!$L:$L,N$1),"") -> 0 | O27: =IFERROR($N27/($N27+$L27),"") -> 0 | R27: =IFERROR(COUNTIFS(데이터!$N:$N,$A$1,데이터!$M:$M,$Q27),"") -> 0 | S27: =IFERROR(SUMIFS(데이터!$G:$G,데이터!$N:$N,$A$1,데이터!$M:$M,$Q27),"") -> 0 | U27: =IFERROR(S27/(SUM($S$3:$S1203)),"") -> 0 | V27: =SUMIFS(데이터!$G:$G,데이터!$N:$N,$A$1,데이터!$M:$M,$Q27,데이터!$L:$L,$V$1) -> 0 | W27: =IFERROR(V27/($V27+$X27),"") | X27: =SUMIFS(데이터!$G:$G,데이터!$N:$N,$A$1,데이터!$M:$M,$Q27,데이터!$L:$L,$X$1) -> 0 | Y27: =IFERROR(X27/($V27+$X27),"")
C28: 모임북 | D28: 모임북 (모임북_150_210_가변하드 무광 / 150X210 | 하드커버 | 없음 | 38p) | E28: 모임북 | F28: =COUNTIFS(데이터!F:F,D28,데이터!$N:$N,$A$1) -> 4 | G28: =SUMIFS(데이터!G:G,데이터!F:F,D28,데이터!$N:$N,$A$1) -> 6 | H28: =IFERROR(G28/F28,0) -> 1.5 | I28: =IFERROR((SUMIFS(데이터!K:K,데이터!F:F,D28,데이터!$N:$N,$A$1))/F28,0) -> 44.5 | J28: =IFERROR($G28/$G$2,"") -> 0.00075709779 | K28: =G28 -> 6 | L28: =IFERROR(SUMIFS(데이터!$G:$G,데이터!$F:$F,$D28,데이터!$N:$N,$A$1,데이터!$L:$L,L$1),"") -> 6 | M28: =IFERROR($L28/($L28+$N28),"") -> 1 | N28: =IFERROR(SUMIFS(데이터!$G:$G,데이터!$F:$F,$D28,데이터!$N:$N,$A$1,데이터!$L:$L,N$1),"") -> 0 | O28: =IFERROR($N28/($N28+$L28),"") -> 0 | R28: =IFERROR(COUNTIFS(데이터!$N:$N,$A$1,데이터!$M:$M,$Q28),"") -> 0 | S28: =IFERROR(SUMIFS(데이터!$G:$G,데이터!$N:$N,$A$1,데이터!$M:$M,$Q28),"") -> 0 | U28: =IFERROR(S28/(SUM($S$3:$S1204)),"") -> 0 | V28: =SUMIFS(데이터!$G:$G,데이터!$N:$N,$A$1,데이터!$M:$M,$Q28,데이터!$L:$L,$V$1) -> 0 | W28: =IFERROR(V28/($V28+$X28),"") | X28: =SUMIFS(데이터!$G:$G,데이터!$N:$N,$A$1,데이터!$M:$M,$Q28,데이터!$L:$L,$X$1) -> 0 | Y28: =IFERROR(X28/($V28+$X28),"")
C29: 반려스토리북 | D29: 반려스토리북 (반려스토리북_130_185_PUR제본_가변 하드_무광 / 130X185 | 하드커버 | 없음 | 46p) | E29: 반려스토리북 | F29: =COUNTIFS(데이터!F:F,D29,데이터!$N:$N,$A$1) -> 1 | G29: =SUMIFS(데이터!G:G,데이터!F:F,D29,데이터!$N:$N,$A$1) -> 1 | H29: =IFERROR(G29/F29,0) -> 1 | I29: =IFERROR((SUMIFS(데이터!K:K,데이터!F:F,D29,데이터!$N:$N,$A$1))/F29,0) -> 48 | J29: =IFERROR($G29/$G$2,"") -> 0.00012618297 | K29: =G29 -> 1 | L29: =IFERROR(SUMIFS(데이터!$G:$G,데이터!$F:$F,$D29,데이터!$N:$N,$A$1,데이터!$L:$L,L$1),"") -> 1 | M29: =IFERROR($L29/($L29+$N29),"") -> 1 | N29: =IFERROR(SUMIFS(데이터!$G:$G,데이터!$F:$F,$D29,데이터!$N:$N,$A$1,데이터!$L:$L,N$1),"") -> 0 | O29: =IFERROR($N29/($N29+$L29),"") -> 0 | R29: =IFERROR(COUNTIFS(데이터!$N:$N,$A$1,데이터!$M:$M,$Q29),"") -> 0 | S29: =IFERROR(SUMIFS(데이터!$G:$G,데이터!$N:$N,$A$1,데이터!$M:$M,$Q29),"") -> 0 | U29: =IFERROR(S29/(SUM($S$3:$S1205)),"") -> 0 | V29: =SUMIFS(데이터!$G:$G,데이터!$N:$N,$A$1,데이터!$M:$M,$Q29,데이터!$L:$L,$V$1) -> 0 | W29: =IFERROR(V29/($V29+$X29),"") | X29: =SUMIFS(데이터!$G:$G,데이터!$N:$N,$A$1,데이터!$M:$M,$Q29,데이터!$L:$L,$X$1) -> 0 | Y29: =IFERROR(X29/($V29+$X29),"")
C30: 반려화보북 | D30: 반려화보북 (반려화보북_197_278_PUR제본_가변 소프트압축_무광 / 197X278 | 소프트압축커버 | 없음 | 46p) | E30: 반려화보북 | F30: =COUNTIFS(데이터!F:F,D30,데이터!$N:$N,$A$1) -> 0 | G30: =SUMIFS(데이터!G:G,데이터!F:F,D30,데이터!$N:$N,$A$1) -> 0 | H30: =IFERROR(G30/F30,0) -> 0 | I30: =IFERROR((SUMIFS(데이터!K:K,데이터!F:F,D30,데이터!$N:$N,$A$1))/F30,0) -> 0 | J30: =IFERROR($G30/$G$2,"") -> 0 | K30: =G30 -> 0 | L30: =IFERROR(SUMIFS(데이터!$G:$G,데이터!$F:$F,$D30,데이터!$N:$N,$A$1,데이터!$L:$L,L$1),"") -> 0 | M30: =IFERROR($L30/($L30+$N30),"") | N30: =IFERROR(SUMIFS(데이터!$G:$G,데이터!$F:$F,$D30,데이터!$N:$N,$A$1,데이터!$L:$L,N$1),"") -> 0 | O30: =IFERROR($N30/($N30+$L30),"") | R30: =IFERROR(COUNTIFS(데이터!$N:$N,$A$1,데이터!$M:$M,$Q30),"") -> 0 | S30: =IFERROR(SUMIFS(데이터!$G:$G,데이터!$N:$N,$A$1,데이터!$M:$M,$Q30),"") -> 0 | U30: =IFERROR(S30/(SUM($S$3:$S1206)),"") -> 0 | V30: =SUMIFS(데이터!$G:$G,데이터!$N:$N,$A$1,데이터!$M:$M,$Q30,데이터!$L:$L,$V$1) -> 0 | W30: =IFERROR(V30/($V30+$X30),"") | X30: =SUMIFS(데이터!$G:$G,데이터!$N:$N,$A$1,데이터!$M:$M,$Q30,데이터!$L:$L,$X$1) -> 0 | Y30: =IFERROR(X30/($V30+$X30),"")
C31: 반야북 | D31: 불교교_반야북_6색_198_198_가변 쿠션하드_무광 / 198X198 | 쿠션하드커버 | 없음 | 58p | E31: 반야북 | F31: =COUNTIFS(데이터!F:F,D31,데이터!$N:$N,$A$1) -> 0 | G31: =SUMIFS(데이터!G:G,데이터!F:F,D31,데이터!$N:$N,$A$1) -> 0 | H31: =IFERROR(G31/F31,0) -> 0 | I31: =IFERROR((SUMIFS(데이터!K:K,데이터!F:F,D31,데이터!$N:$N,$A$1))/F31,0) -> 0 | J31: =IFERROR($G31/$G$2,"") -> 0 | K31: =G31 -> 0 | L31: =IFERROR(SUMIFS(데이터!$G:$G,데이터!$F:$F,$D31,데이터!$N:$N,$A$1,데이터!$L:$L,L$1),"") -> 0 | M31: =IFERROR($L31/($L31+$N31),"") | N31: =IFERROR(SUMIFS(데이터!$G:$G,데이터!$F:$F,$D31,데이터!$N:$N,$A$1,데이터!$L:$L,N$1),"") -> 0 | O31: =IFERROR($N31/($N31+$L31),"") | R31: =IFERROR(COUNTIFS(데이터!$N:$N,$A$1,데이터!$M:$M,$Q31),"") -> 0 | S31: =IFERROR(SUMIFS(데이터!$G:$G,데이터!$N:$N,$A$1,데이터!$M:$M,$Q31),"") -> 0 | U31: =IFERROR(S31/(SUM($S$3:$S1207)),"") -> 0 | V31: =SUMIFS(데이터!$G:$G,데이터!$N:$N,$A$1,데이터!$M:$M,$Q31,데이터!$L:$L,$V$1) -> 0 | W31: =IFERROR(V31/($V31+$X31),"") | X31: =SUMIFS(데이터!$G:$G,데이터!$N:$N,$A$1,데이터!$M:$M,$Q31,데이터!$L:$L,$X$1) -> 0 | Y31: =IFERROR(X31/($V31+$X31),"")
C32: 베이비북 198 | D32: 베이비북_198_198_가변 쿠션하드 (베이비북_198_198_78p_가변 쿠션하드 / 198X198 | 쿠션하드커버 | 없음 | 78p) | E32: 베이비북 198 (쿠션하드/78p) | F32: =COUNTIFS(데이터!F:F,D32,데이터!$N:$N,$A$1) -> 2 | G32: =SUMIFS(데이터!G:G,데이터!F:F,D32,데이터!$N:$N,$A$1) -> 2 | H32: =IFERROR(G32/F32,0) -> 1 | I32: =IFERROR((SUMIFS(데이터!K:K,데이터!F:F,D32,데이터!$N:$N,$A$1))/F32,0) -> 80 | J32: =IFERROR($G32/$G$2,"") -> 0.00025236593 | K32: =SUM(G32:G37) -> 14 | L32: =IFERROR(SUMIFS(데이터!$G:$G,데이터!$F:$F,$D32,데이터!$N:$N,$A$1,데이터!$L:$L,L$1),"") -> 2 | M32: =IFERROR($L32/($L32+$N32),"") -> 1 | N32: =IFERROR(SUMIFS(데이터!$G:$G,데이터!$F:$F,$D32,데이터!$N:$N,$A$1,데이터!$L:$L,N$1),"") -> 0 | O32: =IFERROR($N32/($N32+$L32),"") -> 0 | R32: =IFERROR(COUNTIFS(데이터!$N:$N,$A$1,데이터!$M:$M,$Q32),"") -> 0 | S32: =IFERROR(SUMIFS(데이터!$G:$G,데이터!$N:$N,$A$1,데이터!$M:$M,$Q32),"") -> 0 | U32: =IFERROR(S32/(SUM($S$3:$S1208)),"") -> 0 | V32: =SUMIFS(데이터!$G:$G,데이터!$N:$N,$A$1,데이터!$M:$M,$Q32,데이터!$L:$L,$V$1) -> 0 | W32: =IFERROR(V32/($V32+$X32),"") | X32: =SUMIFS(데이터!$G:$G,데이터!$N:$N,$A$1,데이터!$M:$M,$Q32,데이터!$L:$L,$X$1) -> 0 | Y32: =IFERROR(X32/($V32+$X32),"")
D33: 베이비북_198_198_가변 쿠션하드 (베이비북_198_198_58p_가변 쿠션하드 / 198X198 | 쿠션하드커버 | 없음 | 58p) | E33: 베이비북 198 (쿠션하드/58p) | F33: =COUNTIFS(데이터!F:F,D33,데이터!$N:$N,$A$1) -> 0 | G33: =SUMIFS(데이터!G:G,데이터!F:F,D33,데이터!$N:$N,$A$1) -> 0 | H33: =IFERROR(G33/F33,0) -> 0 | I33: =IFERROR((SUMIFS(데이터!K:K,데이터!F:F,D33,데이터!$N:$N,$A$1))/F33,0) -> 0 | J33: =IFERROR($G33/$G$2,"") -> 0 | L33: =IFERROR(SUMIFS(데이터!$G:$G,데이터!$F:$F,$D33,데이터!$N:$N,$A$1,데이터!$L:$L,L$1),"") -> 0 | M33: =IFERROR($L33/($L33+$N33),"") | N33: =IFERROR(SUMIFS(데이터!$G:$G,데이터!$F:$F,$D33,데이터!$N:$N,$A$1,데이터!$L:$L,N$1),"") -> 0 | O33: =IFERROR($N33/($N33+$L33),"") | R33: =IFERROR(COUNTIFS(데이터!$N:$N,$A$1,데이터!$M:$M,$Q33),"") -> 0 | S33: =IFERROR(SUMIFS(데이터!$G:$G,데이터!$N:$N,$A$1,데이터!$M:$M,$Q33),"") -> 0 | U33: =IFERROR(S33/(SUM($S$3:$S1209)),"") -> 0 | V33: =SUMIFS(데이터!$G:$G,데이터!$N:$N,$A$1,데이터!$M:$M,$Q33,데이터!$L:$L,$V$1) -> 0 | W33: =IFERROR(V33/($V33+$X33),"") | X33: =SUMIFS(데이터!$G:$G,데이터!$N:$N,$A$1,데이터!$M:$M,$Q33,데이터!$L:$L,$X$1) -> 0 | Y33: =IFERROR(X33/($V33+$X33),"")
D34: 베이비북_198_198_가변 쿠션하드 (베이비북_198_198_38p_가변 쿠션하드 / 198X198 | 쿠션하드커버 | 없음 | 38p) | E34: 베이비북 198 (쿠션하드/38p) | F34: =COUNTIFS(데이터!F:F,D34,데이터!$N:$N,$A$1) -> 12 | G34: =SUMIFS(데이터!G:G,데이터!F:F,D34,데이터!$N:$N,$A$1) -> 12 | H34: =IFERROR(G34/F34,0) -> 1 | I34: =IFERROR((SUMIFS(데이터!K:K,데이터!F:F,D34,데이터!$N:$N,$A$1))/F34,0) -> 40 | J34: =IFERROR($G34/$G$2,"") -> 0.0015141956 | L34: =IFERROR(SUMIFS(데이터!$G:$G,데이터!$F:$F,$D34,데이터!$N:$N,$A$1,데이터!$L:$L,L$1),"") -> 12 | M34: =IFERROR($L34/($L34+$N34),"") -> 1 | N34: =IFERROR(SUMIFS(데이터!$G:$G,데이터!$F:$F,$D34,데이터!$N:$N,$A$1,데이터!$L:$L,N$1),"") -> 0 | O34: =IFERROR($N34/($N34+$L34),"") -> 0 | R34: =IFERROR(COUNTIFS(데이터!$N:$N,$A$1,데이터!$M:$M,$Q34),"") -> 0 | S34: =IFERROR(SUMIFS(데이터!$G:$G,데이터!$N:$N,$A$1,데이터!$M:$M,$Q34),"") -> 0 | U34: =IFERROR(S34/(SUM($S$3:$S1210)),"") -> 0 | V34: =SUMIFS(데이터!$G:$G,데이터!$N:$N,$A$1,데이터!$M:$M,$Q34,데이터!$L:$L,$V$1) -> 0 | W34: =IFERROR(V34/($V34+$X34),"") | X34: =SUMIFS(데이터!$G:$G,데이터!$N:$N,$A$1,데이터!$M:$M,$Q34,데이터!$L:$L,$X$1) -> 0 | Y34: =IFERROR(X34/($V34+$X34),"")
D35: 베이비북_198_198_78p_가변 소프트 / 198X198| 소프트커버 | 없음 | 78p | E35: 베이비북 198 (소프트/78p) | F35: =COUNTIFS(데이터!F:F,D35,데이터!$N:$N,$A$1) -> 0 | G35: =SUMIFS(데이터!G:G,데이터!F:F,D35,데이터!$N:$N,$A$1) -> 0 | H35: =IFERROR(G35/F35,0) -> 0 | I35: =IFERROR((SUMIFS(데이터!K:K,데이터!F:F,D35,데이터!$N:$N,$A$1))/F35,0) -> 0 | J35: =IFERROR($G35/$G$2,"") -> 0 | L35: =IFERROR(SUMIFS(데이터!$G:$G,데이터!$F:$F,$D35,데이터!$N:$N,$A$1,데이터!$L:$L,L$1),"") -> 0 | M35: =IFERROR($L35/($L35+$N35),"") | N35: =IFERROR(SUMIFS(데이터!$G:$G,데이터!$F:$F,$D35,데이터!$N:$N,$A$1,데이터!$L:$L,N$1),"") -> 0 | O35: =IFERROR($N35/($N35+$L35),"") | R35: =IFERROR(COUNTIFS(데이터!$N:$N,$A$1,데이터!$M:$M,$Q35),"") -> 0 | S35: =IFERROR(SUMIFS(데이터!$G:$G,데이터!$N:$N,$A$1,데이터!$M:$M,$Q35),"") -> 0 | U35: =IFERROR(S35/(SUM($S$3:$S1211)),"") -> 0 | V35: =SUMIFS(데이터!$G:$G,데이터!$N:$N,$A$1,데이터!$M:$M,$Q35,데이터!$L:$L,$V$1) -> 0 | W35: =IFERROR(V35/($V35+$X35),"") | X35: =SUMIFS(데이터!$G:$G,데이터!$N:$N,$A$1,데이터!$M:$M,$Q35,데이터!$L:$L,$X$1) -> 0 | Y35: =IFERROR(X35/($V35+$X35),"")
D36: 베이비북_198_198_가변 소프트 (베이비북_198_198_58p_가변 소프트 / 198X198|소프트커버|없음|58p) | E36: 베이비북 198 (소프트/58p) | F36: =COUNTIFS(데이터!F:F,D36,데이터!$N:$N,$A$1) -> 0 | G36: =SUMIFS(데이터!G:G,데이터!F:F,D36,데이터!$N:$N,$A$1) -> 0 | H36: =IFERROR(G36/F36,0) -> 0 | I36: =IFERROR((SUMIFS(데이터!K:K,데이터!F:F,D36,데이터!$N:$N,$A$1))/F36,0) -> 0 | J36: =IFERROR($G36/$G$2,"") -> 0 | L36: =IFERROR(SUMIFS(데이터!$G:$G,데이터!$F:$F,$D36,데이터!$N:$N,$A$1,데이터!$L:$L,L$1),"") -> 0 | M36: =IFERROR($L36/($L36+$N36),"") | N36: =IFERROR(SUMIFS(데이터!$G:$G,데이터!$F:$F,$D36,데이터!$N:$N,$A$1,데이터!$L:$L,N$1),"") -> 0 | O36: =IFERROR($N36/($N36+$L36),"") | R36: =IFERROR(COUNTIFS(데이터!$N:$N,$A$1,데이터!$M:$M,$Q36),"") -> 0 | S36: =IFERROR(SUMIFS(데이터!$G:$G,데이터!$N:$N,$A$1,데이터!$M:$M,$Q36),"") -> 0 | U36: =IFERROR(S36/(SUM($S$3:$S1212)),"") -> 0 | V36: =SUMIFS(데이터!$G:$G,데이터!$N:$N,$A$1,데이터!$M:$M,$Q36,데이터!$L:$L,$V$1) -> 0 | W36: =IFERROR(V36/($V36+$X36),"") | X36: =SUMIFS(데이터!$G:$G,데이터!$N:$N,$A$1,데이터!$M:$M,$Q36,데이터!$L:$L,$X$1) -> 0 | Y36: =IFERROR(X36/($V36+$X36),"")
D37: 베이비북_198_198_38p_가변 소프트 / 198X198| 소프트커버 | 없음 | 38p | E37: 베이비북 198 (소프트/38p) | F37: =COUNTIFS(데이터!F:F,D37,데이터!$N:$N,$A$1) -> 0 | G37: =SUMIFS(데이터!G:G,데이터!F:F,D37,데이터!$N:$N,$A$1) -> 0 | H37: =IFERROR(G37/F37,0) -> 0 | I37: =IFERROR((SUMIFS(데이터!K:K,데이터!F:F,D37,데이터!$N:$N,$A$1))/F37,0) -> 0 | J37: =IFERROR($G37/$G$2,"") -> 0 | L37: =IFERROR(SUMIFS(데이터!$G:$G,데이터!$F:$F,$D37,데이터!$N:$N,$A$1,데이터!$L:$L,L$1),"") -> 0 | M37: =IFERROR($L37/($L37+$N37),"") | N37: =IFERROR(SUMIFS(데이터!$G:$G,데이터!$F:$F,$D37,데이터!$N:$N,$A$1,데이터!$L:$L,N$1),"") -> 0 | O37: =IFERROR($N37/($N37+$L37),"") | R37: =IFERROR(COUNTIFS(데이터!$N:$N,$A$1,데이터!$M:$M,$Q37),"") -> 0 | S37: =IFERROR(SUMIFS(데이터!$G:$G,데이터!$N:$N,$A$1,데이터!$M:$M,$Q37),"") -> 0 | U37: =IFERROR(S37/(SUM($S$3:$S1213)),"") -> 0 | V37: =SUMIFS(데이터!$G:$G,데이터!$N:$N,$A$1,데이터!$M:$M,$Q37,데이터!$L:$L,$V$1) -> 0 | W37: =IFERROR(V37/($V37+$X37),"") | X37: =SUMIFS(데이터!$G:$G,데이터!$N:$N,$A$1,데이터!$M:$M,$Q37,데이터!$L:$L,$X$1) -> 0 | Y37: =IFERROR(X37/($V37+$X37),"")
C38: 베이비북 197 | D38: 베이비북_197_278_가변 쿠션하드 (베이비북_197_278_78p_가변 쿠션하드 / 197X278 | 쿠션하드커버 | 없음 | 78p) | E38: 베이비북 197 (쿠션하드/78p) | F38: =COUNTIFS(데이터!F:F,D38,데이터!$N:$N,$A$1) -> 0 | G38: =SUMIFS(데이터!G:G,데이터!F:F,D38,데이터!$N:$N,$A$1) -> 0 | H38: =IFERROR(G38/F38,0) -> 0 | I38: =IFERROR((SUMIFS(데이터!K:K,데이터!F:F,D38,데이터!$N:$N,$A$1))/F38,0) -> 0 | J38: =IFERROR($G38/$G$2,"") -> 0 | K38: =SUM(G38:G43) -> 0 | L38: =IFERROR(SUMIFS(데이터!$G:$G,데이터!$F:$F,$D38,데이터!$N:$N,$A$1,데이터!$L:$L,L$1),"") -> 0 | M38: =IFERROR($L38/($L38+$N38),"") | N38: =IFERROR(SUMIFS(데이터!$G:$G,데이터!$F:$F,$D38,데이터!$N:$N,$A$1,데이터!$L:$L,N$1),"") -> 0 | O38: =IFERROR($N38/($N38+$L38),"") | R38: =IFERROR(COUNTIFS(데이터!$N:$N,$A$1,데이터!$M:$M,$Q38),"") -> 0 | S38: =IFERROR(SUMIFS(데이터!$G:$G,데이터!$N:$N,$A$1,데이터!$M:$M,$Q38),"") -> 0 | U38: =IFERROR(S38/(SUM($S$3:$S1214)),"") -> 0 | V38: =SUMIFS(데이터!$G:$G,데이터!$N:$N,$A$1,데이터!$M:$M,$Q38,데이터!$L:$L,$V$1) -> 0 | W38: =IFERROR(V38/($V38+$X38),"") | X38: =SUMIFS(데이터!$G:$G,데이터!$N:$N,$A$1,데이터!$M:$M,$Q38,데이터!$L:$L,$X$1) -> 0 | Y38: =IFERROR(X38/($V38+$X38),"")
D39: 베이비북_198_198_58p_가변 쿠션하드 / 198X198 | 쿠션하드커버 | 없음 | 58p | E39: 베이비북 197 (쿠션하드/58p) | F39: =COUNTIFS(데이터!F:F,D39,데이터!$N:$N,$A$1) -> 0 | G39: =SUMIFS(데이터!G:G,데이터!F:F,D39,데이터!$N:$N,$A$1) -> 0 | H39: =IFERROR(G39/F39,0) -> 0 | I39: =IFERROR((SUMIFS(데이터!K:K,데이터!F:F,D39,데이터!$N:$N,$A$1))/F39,0) -> 0 | J39: =IFERROR($G39/$G$2,"") -> 0 | L39: =IFERROR(SUMIFS(데이터!$G:$G,데이터!$F:$F,$D39,데이터!$N:$N,$A$1,데이터!$L:$L,L$1),"") -> 0 | M39: =IFERROR($L39/($L39+$N39),"") | N39: =IFERROR(SUMIFS(데이터!$G:$G,데이터!$F:$F,$D39,데이터!$N:$N,$A$1,데이터!$L:$L,N$1),"") -> 0 | O39: =IFERROR($N39/($N39+$L39),"") | R39: =IFERROR(COUNTIFS(데이터!$N:$N,$A$1,데이터!$M:$M,$Q39),"") -> 0 | S39: =IFERROR(SUMIFS(데이터!$G:$G,데이터!$N:$N,$A$1,데이터!$M:$M,$Q39),"") -> 0 | U39: =IFERROR(S39/(SUM($S$3:$S1215)),"") -> 0 | V39: =SUMIFS(데이터!$G:$G,데이터!$N:$N,$A$1,데이터!$M:$M,$Q39,데이터!$L:$L,$V$1) -> 0 | W39: =IFERROR(V39/($V39+$X39),"") | X39: =SUMIFS(데이터!$G:$G,데이터!$N:$N,$A$1,데이터!$M:$M,$Q39,데이터!$L:$L,$X$1) -> 0 | Y39: =IFERROR(X39/($V39+$X39),"")
D40: 베이비북_198_198_38p_가변 쿠션하드 / 198X198 | 쿠션하드커버 | 없음 | 38p | E40: 베이비북 197 (쿠션하드/38p) | F40: =COUNTIFS(데이터!F:F,D40,데이터!$N:$N,$A$1) -> 0 | G40: =SUMIFS(데이터!G:G,데이터!F:F,D40,데이터!$N:$N,$A$1) -> 0 | H40: =IFERROR(G40/F40,0) -> 0 | I40: =IFERROR((SUMIFS(데이터!K:K,데이터!F:F,D40,데이터!$N:$N,$A$1))/F40,0) -> 0 | J40: =IFERROR($G40/$G$2,"") -> 0 | L40: =IFERROR(SUMIFS(데이터!$G:$G,데이터!$F:$F,$D40,데이터!$N:$N,$A$1,데이터!$L:$L,L$1),"") -> 0 | M40: =IFERROR($L40/($L40+$N40),"") | N40: =IFERROR(SUMIFS(데이터!$G:$G,데이터!$F:$F,$D40,데이터!$N:$N,$A$1,데이터!$L:$L,N$1),"") -> 0 | O40: =IFERROR($N40/($N40+$L40),"") | R40: =IFERROR(COUNTIFS(데이터!$N:$N,$A$1,데이터!$M:$M,$Q40),"") -> 0 | S40: =IFERROR(SUMIFS(데이터!$G:$G,데이터!$N:$N,$A$1,데이터!$M:$M,$Q40),"") -> 0 | U40: =IFERROR(S40/(SUM($S$3:$S1216)),"") -> 0 | V40: =SUMIFS(데이터!$G:$G,데이터!$N:$N,$A$1,데이터!$M:$M,$Q40,데이터!$L:$L,$V$1) -> 0 | W40: =IFERROR(V40/($V40+$X40),"") | X40: =SUMIFS(데이터!$G:$G,데이터!$N:$N,$A$1,데이터!$M:$M,$Q40,데이터!$L:$L,$X$1) -> 0 | Y40: =IFERROR(X40/($V40+$X40),"")
...

Sheet 월간집계
A1: 2026 | B1: 5 | C1: 판매상품명 | D1: 상품명 | E1: 상품명 | F1: 건수 | G1: 부수 | H1: 평균부수 | I1: 평균페이지 | J1: 비율 | K1: 소계 | L1: PC | N1: MO | Q1: 구분 | R1: 주문건수 | S1: 주문부수 | T1: 비율 | U1: PC | W1: MO
F2: =SUM(F3:F1179) -> 644 | G2: =SUM(G3:G1179) -> 1021 | H2: =IFERROR(G2/F2,"") -> 1.5854037 | L2: =SUM(L3:L1179) -> 922 | M2: =IFERROR($L2/($L2+$N2),"") -> 0.90303624 | N2: =SUM(N3:N1179) -> 99 | O2: =IFERROR($N2/($N2+$L2),"") -> 0.096963761 | Q2: =COUNTA(Q3:Q1179) -> 18 | R2: =SUM(R3:R1179) -> 644 | S2: =SUM(S3:S1179) -> 1021 | U2: =SUM(U3:U1179) -> 922 | V2: =IFERROR(U2/($U2+$W2),"") -> 0.90303624 | W2: =SUM(W3:W1179) -> 99 | X2: =IFERROR(W2/($U2+$W2),"") -> 0.096963761
A3: 포토북 | B3: 스탠다드 | C3: 150*210 | D3: =연간집계!D3 -> PCMS_150_210 (PCMS_150_210_소프트커버_무광 / 150x210 | 소프트커버무광 | 없음 | 22p) | E3: =연간집계!E3 -> 스탠다드 포토북 6*8 (소프트/무광) | F3: =COUNTIFS(데이터!F:F,D3,데이터!$N:$N,$A$1,데이터!$O:$O,$B$1) -> 8 | G3: =SUMIFS(데이터!G:G,데이터!F:F,D3,데이터!$N:$N,$A$1,데이터!$O:$O,$B$1) -> 13 | H3: =IFERROR(G3/F3,0) -> 1.625 | I3: =IFERROR((SUMIFS(데이터!K:K,데이터!F:F,D3,데이터!$N:$N,$A$1,데이터!$O:$O,$B$1))/F3,0) -> 36.5 | J3: =IFERROR($G3/$G$2,"") -> 0.012732615 | K3: =SUM(G3:G6) -> 158 | L3: =IFERROR(SUMIFS(데이터!$G:$G,데이터!$F:$F,$D3,데이터!$N:$N,$A$1,데이터!$O:$O,$B$1,데이터!$L:$L,L$1),"") -> 13 | M3: =IFERROR($L3/($L3+$N3),"") -> 1 | N3: =IFERROR(SUMIFS(데이터!$G:$G,데이터!$F:$F,$D3,데이터!$N:$N,$A$1,데이터!$O:$O,$B$1,데이터!$L:$L,N$1),"") -> 0 | O3: =IFERROR($N3/($N3+$L3),"") -> 0 | Q3: =IFERROR(__xludf.DUMMYFUNCTION("iferror(SORT( UNIQUE( FILTER( '데이터'!$M:$M, '데이터'!$N:$N = $A$1, '데이터'!$O:$O = $B$1, '데이터'!$M:$M <> """" ) ), 1, TRUE ),""-"")"),"01.여행 : 개인/가족") -> 01.여행 : 개인/가족 | R3: =IFERROR(COUNTIFS(데이터!$N:$N,$A$1,데이터!$O:$O,$B$1,데이터!$M:$M,$Q3),"") -> 304 | S3: =IFERROR(SUMIFS(데이터!$G:$G,데이터!$N:$N,$A$1,데이터!$O:$O,$B$1,데이터!$M:$M,$Q3),"") -> 396 | T3: =IFERROR(S3/(SUM($S$3:$S1179)),"") -> 0.38785504 | U3: =SUMIFS(데이터!$G:$G,데이터!$N:$N,$A$1,데이터!$O:$O,$B$1,데이터!$M:$M,$Q3,데이터!$L:$L,$U$1) -> 349 | V3: =IFERROR(U3/($U3+$W3),"") -> 0.88131313 | W3: =SUMIFS(데이터!$G:$G,데이터!$N:$N,$A$1,데이터!$O:$O,$B$1,데이터!$M:$M,$Q3,데이터!$L:$L,$W$1) -> 47 | X3: =IFERROR(W3/($U3+$W3),"") -> 0.11868687
D4: =연간집계!D4 -> PCMS_150_210 (PCMS_150_210_소프트커버_유광 / 150x210 | 소프트커버유광 | 없음 | 22p) | E4: =연간집계!E4 -> 스탠다드 포토북 6*8 (소프트/유광) | F4: =COUNTIFS(데이터!F:F,D4,데이터!$N:$N,$A$1,데이터!$O:$O,$B$1) -> 1 | G4: =SUMIFS(데이터!G:G,데이터!F:F,D4,데이터!$N:$N,$A$1,데이터!$O:$O,$B$1) -> 1 | H4: =IFERROR(G4/F4,0) -> 1 | I4: =IFERROR((SUMIFS(데이터!K:K,데이터!F:F,D4,데이터!$N:$N,$A$1,데이터!$O:$O,$B$1))/F4,0) -> 28 | J4: =IFERROR($G4/$G$2,"") -> 0.00097943193 | L4: =IFERROR(SUMIFS(데이터!$G:$G,데이터!$F:$F,$D4,데이터!$N:$N,$A$1,데이터!$O:$O,$B$1,데이터!$L:$L,L$1),"") -> 1 | M4: =IFERROR($L4/($L4+$N4),"") -> 1 | N4: =IFERROR(SUMIFS(데이터!$G:$G,데이터!$F:$F,$D4,데이터!$N:$N,$A$1,데이터!$O:$O,$B$1,데이터!$L:$L,N$1),"") -> 0 | O4: =IFERROR($N4/($N4+$L4),"") -> 0 | Q4: =IFERROR(__xludf.DUMMYFUNCTION("""COMPUTED_VALUE"""),"01.여행 : 단체/모임/친구") -> 01.여행 : 단체/모임/친구 | R4: =IFERROR(COUNTIFS(데이터!$N:$N,$A$1,데이터!$O:$O,$B$1,데이터!$M:$M,$Q4),"") -> 58 | S4: =IFERROR(SUMIFS(데이터!$G:$G,데이터!$N:$N,$A$1,데이터!$O:$O,$B$1,데이터!$M:$M,$Q4),"") -> 141 | T4: =IFERROR(S4/(SUM($S$3:$S1180)),"") -> 0.1380999 | U4: =SUMIFS(데이터!$G:$G,데이터!$N:$N,$A$1,데이터!$O:$O,$B$1,데이터!$M:$M,$Q4,데이터!$L:$L,$U$1) -> 132 | V4: =IFERROR(U4/($U4+$W4),"") -> 0.93617021 | W4: =SUMIFS(데이터!$G:$G,데이터!$N:$N,$A$1,데이터!$O:$O,$B$1,데이터!$M:$M,$Q4,데이터!$L:$L,$W$1) -> 9 | X4: =IFERROR(W4/($U4+$W4),"") -> 0.063829787
D5: =연간집계!D5 -> PCMS_150_210 (PCMS_150_210_하드커버_무광 / 150x210 | 하드커버무광 | 없음 | 22p) | E5: =연간집계!E5 -> 스탠다드 포토북 6*8 (하드/무광) | F5: =COUNTIFS(데이터!F:F,D5,데이터!$N:$N,$A$1,데이터!$O:$O,$B$1) -> 92 | G5: =SUMIFS(데이터!G:G,데이터!F:F,D5,데이터!$N:$N,$A$1,데이터!$O:$O,$B$1) -> 131 | H5: =IFERROR(G5/F5,0) -> 1.423913 | I5: =IFERROR((SUMIFS(데이터!K:K,데이터!F:F,D5,데이터!$N:$N,$A$1,데이터!$O:$O,$B$1))/F5,0) -> 40.173913 | J5: =IFERROR($G5/$G$2,"") -> 0.12830558 | L5: =IFERROR(SUMIFS(데이터!$G:$G,데이터!$F:$F,$D5,데이터!$N:$N,$A$1,데이터!$O:$O,$B$1,데이터!$L:$L,L$1),"") -> 131 | M5: =IFERROR($L5/($L5+$N5),"") -> 1 | N5: =IFERROR(SUMIFS(데이터!$G:$G,데이터!$F:$F,$D5,데이터!$N:$N,$A$1,데이터!$O:$O,$B$1,데이터!$L:$L,N$1),"") -> 0 | O5: =IFERROR($N5/($N5+$L5),"") -> 0 | Q5: =IFERROR(__xludf.DUMMYFUNCTION("""COMPUTED_VALUE"""),"01.여행 : 커플") -> 01.여행 : 커플 | R5: =IFERROR(COUNTIFS(데이터!$N:$N,$A$1,데이터!$O:$O,$B$1,데이터!$M:$M,$Q5),"") -> 17 | S5: =IFERROR(SUMIFS(데이터!$G:$G,데이터!$N:$N,$A$1,데이터!$O:$O,$B$1,데이터!$M:$M,$Q5),"") -> 18 | T5: =IFERROR(S5/(SUM($S$3:$S1181)),"") -> 0.017629775 | U5: =SUMIFS(데이터!$G:$G,데이터!$N:$N,$A$1,데이터!$O:$O,$B$1,데이터!$M:$M,$Q5,데이터!$L:$L,$U$1) -> 17 | V5: =IFERROR(U5/($U5+$W5),"") -> 0.94444444 | W5: =SUMIFS(데이터!$G:$G,데이터!$N:$N,$A$1,데이터!$O:$O,$B$1,데이터!$M:$M,$Q5,데이터!$L:$L,$W$1) -> 1 | X5: =IFERROR(W5/($U5+$W5),"") -> 0.055555556
D6: =연간집계!D6 -> PCMS_150_210 (PCMS_150_210_하드커버_유광 / 150x210 | 하드커버유광 | 없음 | 22p) | E6: =연간집계!E6 -> 스탠다드 포토북 6*8 (하드/유광) | F6: =COUNTIFS(데이터!F:F,D6,데이터!$N:$N,$A$1,데이터!$O:$O,$B$1) -> 8 | G6: =SUMIFS(데이터!G:G,데이터!F:F,D6,데이터!$N:$N,$A$1,데이터!$O:$O,$B$1) -> 13 | H6: =IFERROR(G6/F6,0) -> 1.625 | I6: =IFERROR((SUMIFS(데이터!K:K,데이터!F:F,D6,데이터!$N:$N,$A$1,데이터!$O:$O,$B$1))/F6,0) -> 43.25 | J6: =IFERROR($G6/$G$2,"") -> 0.012732615 | L6: =IFERROR(SUMIFS(데이터!$G:$G,데이터!$F:$F,$D6,데이터!$N:$N,$A$1,데이터!$O:$O,$B$1,데이터!$L:$L,L$1),"") -> 13 | M6: =IFERROR($L6/($L6+$N6),"") -> 1 | N6: =IFERROR(SUMIFS(데이터!$G:$G,데이터!$F:$F,$D6,데이터!$N:$N,$A$1,데이터!$O:$O,$B$1,데이터!$L:$L,N$1),"") -> 0 | O6: =IFERROR($N6/($N6+$L6),"") -> 0 | Q6: =IFERROR(__xludf.DUMMYFUNCTION("""COMPUTED_VALUE"""),"02.일상 : 개인/가족") -> 02.일상 : 개인/가족 | R6: =IFERROR(COUNTIFS(데이터!$N:$N,$A$1,데이터!$O:$O,$B$1,데이터!$M:$M,$Q6),"") -> 18 | S6: =IFERROR(SUMIFS(데이터!$G:$G,데이터!$N:$N,$A$1,데이터!$O:$O,$B$1,데이터!$M:$M,$Q6),"") -> 22 | T6: =IFERROR(S6/(SUM($S$3:$S1182)),"") -> 0.021547502 | U6: =SUMIFS(데이터!$G:$G,데이터!$N:$N,$A$1,데이터!$O:$O,$B$1,데이터!$M:$M,$Q6,데이터!$L:$L,$U$1) -> 17 | V6: =IFERROR(U6/($U6+$W6),"") -> 0.77272727 | W6: =SUMIFS(데이터!$G:$G,데이터!$N:$N,$A$1,데이터!$O:$O,$B$1,데이터!$M:$M,$Q6,데이터!$L:$L,$W$1) -> 5 | X6: =IFERROR(W6/($U6+$W6),"") -> 0.22727273
